Workbook

Sheet 2020
A1: Provinsi | B1: Kabupaten/Kota | C1: IPM | D1: IPG | E1: PPM | F1: PDRB_ADHK | G1: RLS | H1: AHH_L | I1: AHH_P | J1: GK | K1: PKKP | L1: TPT | M1: TPAK | N1: GR | O1: JP | Q1: RV
A2: DKI JAKARTA | B2: Kep. Seribu | C2: 71.63 | D2: 93.39 | E2: 14.87 | F2: 3706.25 | G2: 8.68 | H2: 66.67 | I2: 70.74 | J2: 661852 | K2: 2.86 | L2: 7.37 | M2: 60.7 | N2: 0.306 | O2: 27749 | Q2: =CORREL(C$2:C$42,C$2:C$42) -> 1 | R2: =CORREL(C$2:C$42,D$2:D$42) -> 0.7707225 | S2: =CORREL(C$2:C$42,E$2:E$42) -> -0.69640159 | T2: =CORREL(C$2:C$42,F$2:F$42) -> 0.64494491 | U2: =CORREL(C$2:C$42,G$2:G$42) -> 0.9626751 | V2: =CORREL(C$2:C$42,H$2:H$42) -> 0.65217837 | W2: =CORREL(C$2:C$42,I$2:I$42) -> 0.65118053 | X2: =CORREL(C$2:C$42,J$2:J$42) -> 0.84541092 | Y2: =CORREL(C$2:C$42,K$2:K$42) -> -0.70458464 | Z2: =CORREL(C$2:C$42,L$2:L$42) -> 0.23498053 | AA2: =CORREL(C$2:C$42,M$2:M$42) -> -0.24657195 | AB2: =CORREL(C$2:C$42,N$2:N$42) -> 0.53243255
A3: DKI JAKARTA | B3: Kota Jakarta Selatan | C3: 84.72 | D3: 96.14 | E3: 3.43 | F3: 419257.19 | G3: 11.63 | H3: 72.23 | I3: 76.04 | J3: 782731 | K3: 1.5 | L3: 10.79 | M3: 63.81 | N3: 0.427 | O3: 2226812 | Q3: =R2 -> 0.7707225 | R3: =CORREL(D$2:D$42,D$2:D$42) -> 1 | S3: =CORREL(D$2:D$42,E$2:E$42) -> -0.48205546 | T3: =CORREL(D$2:D$42,F$2:F$42) -> 0.48478429 | U3: =CORREL(D$2:D$42,G$2:G$42) -> 0.73134476 | V3: =CORREL(D$2:D$42,H$2:H$42) -> 0.39433983 | W3: =CORREL(D$2:D$42,I$2:I$42) -> 0.39385125 | X3: =CORREL(D$2:D$42,J$2:J$42) -> 0.65707633 | Y3: =CORREL(D$2:D$42,K$2:K$42) -> -0.5654964 | Z3: =CORREL(D$2:D$42,L$2:L$42) -> 0.086230032 | AA3: =CORREL(D$2:D$42,M$2:M$42) -> -0.1165227 | AB3: =CORREL(D$2:D$42,N$2:N$42) -> 0.36143844
A4: DKI JAKARTA | B4: Kota Jakarta Timur | C4: 82.66 | D4: 95.48 | E4: 4.16 | F4: 299515.16 | G4: 11.66 | H4: 72.6 | I4: 76.22 | J4: 581954 | K4: 2.18 | L4: 9.29 | M4: 61.98 | N4: 0.363 | O4: 3037139 | Q4: =S2 -> -0.69640159 | R4: =S3 -> -0.48205546 | S4: =CORREL(E$2:E$42,E$2:E$42) -> 1 | T4: =CORREL(E$2:E$42,F$2:F$42) -> -0.50484694 | U4: =CORREL(E$2:E$42,G$2:G$42) -> -0.70945541 | V4: =CORREL(E$2:E$42,H$2:H$42) -> -0.25953496 | W4: =CORREL(E$2:E$42,I$2:I$42) -> -0.25285961 | X4: =CORREL(E$2:E$42,J$2:J$42) -> -0.49471121 | Y4: =CORREL(E$2:E$42,K$2:K$42) -> 0.68505587 | Z4: =CORREL(E$2:E$42,L$2:L$42) -> -0.29591909 | AA4: =CORREL(E$2:E$42,M$2:M$42) -> 0.18782887 | AB4: =CORREL(E$2:E$42,N$2:N$42) -> -0.27070574
A5: DKI JAKARTA | B5: Kota Jakarta Pusat | C5: 81.39 | D5: 96 | E5: 4.51 | F5: 449518.14 | G5: 11.38 | H5: 72.22 | I5: 75.92 | J5: 672328 | K5: 1.97 | L5: 10.97 | M5: 63.73 | N5: 0.39 | O5: 1056896 | Q5: =T2 -> 0.64494491 | R5: =T3 -> 0.48478429 | S5: =T4 -> -0.50484694 | T5: =CORREL(F$2:F$42,F$2:F$42) -> 1 | U5: =CORREL(F$2:F$42,G$2:G$42) -> 0.55174514 | V5: =CORREL(F$2:F$42,H$2:H$42) -> 0.41150936 | W5: =CORREL(F$2:F$42,I$2:I$42) -> 0.4103952 | X5: =CORREL(F$2:F$42,J$2:J$42) -> 0.56977025 | Y5: =CORREL(F$2:F$42,K$2:K$42) -> -0.47488257 | Z5: =CORREL(F$2:F$42,L$2:L$42) -> 0.304137 | AA5: =CORREL(F$2:F$42,M$2:M$42) -> -0.097335432 | AB5: =CORREL(F$2:F$42,N$2:N$42) -> 0.40207041
A6: DKI JAKARTA | B6: Kota Jakarta Barat | C6: 81.38 | D6: 95.16 | E6: 4.25 | F6: 316172.61 | G6: 10.63 | H6: 71.72 | I6: 75.43 | J6: 557803 | K6: 1.78 | L6: 12.27 | M6: 64.37 | N6: 0.38 | O6: 2434511 | Q6: =U2 -> 0.9626751 | R6: =U3 -> 0.73134476 | S6: =U4 -> -0.70945541 | T6: =U5 -> 0.55174514 | U6: =CORREL(G$2:G$42,G$2:G$42) -> 1 | V6: =CORREL(G$2:G$42,H$2:H$42) -> 0.56126955 | W6: =CORREL(G$2:G$42,I$2:I$42) -> 0.55945797 | X6: =CORREL(G$2:G$42,J$2:J$42) -> 0.81601009 | Y6: =CORREL(G$2:G$42,K$2:K$42) -> -0.70988901 | Z6: =CORREL(G$2:G$42,L$2:L$42) -> 0.24222831 | AA6: =CORREL(G$2:G$42,M$2:M$42) -> -0.31799879 | AB6: =CORREL(G$2:G$42,N$2:N$42) -> 0.55070546
A7: DKI JAKARTA | B7: Kota Jakarta Utara | C7: 80.29 | D7: 93.53 | E7: 6.78 | F7: 312100.58 | G7: 10.8 | H7: 71.36 | I7: 75.13 | J7: 594240 | K7: 2.18 | L7: 11.79 | M7: 65.97 | N7: 0.413 | O7: 1778981 | Q7: =V2 -> 0.65217837 | R7: =V3 -> 0.39433983 | S7: =V4 -> -0.25953496 | T7: =V5 -> 0.41150936 | U7: =V6 -> 0.56126955 | V7: =CORREL(H$2:H$42,H$2:H$42) -> 1 | W7: =CORREL(H$2:H$42,I$2:I$42) -> 0.99945481 | X7: =CORREL(H$2:H$42,J$2:J$42) -> 0.44257979 | Y7: =CORREL(H$2:H$42,K$2:K$42) -> -0.10617802 | Z7: =CORREL(H$2:H$42,L$2:L$42) -> 0.12915119 | AA7: =CORREL(H$2:H$42,M$2:M$42) -> -0.054708653 | AB7: =CORREL(H$2:H$42,N$2:N$42) -> 0.57401025
A8: JAWA BARAT | B8: Bogor | C8: 70.4 | D8: 89.23 | E8: 7.69 | F8: 154113.6 | G8: 8.3 | H8: 69.24 | I8: 73.06 | J8: 402877 | K8: 4.06 | L8: 14.29 | M8: 62.65 | N8: 0.381 | O8: 5409370 | Q8: =W2 -> 0.65118053 | R8: =W3 -> 0.39385125 | S8: =W4 -> -0.25285961 | T8: =W5 -> 0.4103952 | U8: =W6 -> 0.55945797 | V8: =W7 -> 0.99945481 | W8: =CORREL(I$2:I$42,I$2:I$42) -> 1 | X8: =CORREL(I$2:I$42,J$2:J$42) -> 0.44885923 | Y8: =CORREL(I$2:I$42,K$2:K$42) -> -0.10736476 | Z8: =CORREL(I$2:I$42,L$2:L$42) -> 0.12080251 | AA8: =CORREL(I$2:I$42,M$2:M$42) -> -0.051207833 | AB8: =CORREL(I$2:I$42,N$2:N$42) -> 0.57117617
A9: JAWA BARAT | B9: Sukabumi | C9: 66.88 | D9: 87.37 | E9: 7.09 | F9: 46205.28 | G9: 7.07 | H9: 69.03 | I9: 72.87 | J9: 328284 | K9: 4.89 | L9: 9.6 | M9: 61.56 | N9: 0.334 | O9: 2718740 | Q9: =X2 -> 0.84541092 | R9: =X3 -> 0.65707633 | S9: =X4 -> -0.49471121 | T9: =X5 -> 0.56977025 | U9: =X6 -> 0.81601009 | V9: =X7 -> 0.44257979 | W9: =X8 -> 0.44885923 | X9: =CORREL(J$2:J$42,J$2:J$42) -> 1 | Y9: =CORREL(J$2:J$42,K$2:K$42) -> -0.7456931 | Z9: =CORREL(J$2:J$42,L$2:L$42) -> 0.16855083 | AA9: =CORREL(J$2:J$42,M$2:M$42) -> -0.2310517 | AB9: =CORREL(J$2:J$42,N$2:N$42) -> 0.27534691
A10: JAWA BARAT | B10: Cianjur | C10: 65.36 | D10: 84.14 | E10: 10.36 | F10: 31792.32 | G10: 7.18 | H10: 68.17 | I10: 72.03 | J10: 371699 | K10: 4.75 | L10: 11.05 | M10: 69.26 | N10: 0.35 | O10: 2470560 | Q10: =Y2 -> -0.70458464 | R10: =Y3 -> -0.5654964 | S10: =Y4 -> 0.68505587 | T10: =Y5 -> -0.47488257 | U10: =Y6 -> -0.70988901 | V10: =Y7 -> -0.10617802 | W10: =Y8 -> -0.10736476 | X10: =Y9 -> -0.7456931 | Y10: =CORREL(K$2:K$42,K$2:K$42) -> 1 | Z10: =CORREL(K$2:K$42,L$2:L$42) -> -0.28630068 | AA10: =CORREL(K$2:K$42,M$2:M$42) -> 0.23759144 | AB10: =CORREL(K$2:K$42,N$2:N$42) -> -0.062609456
A11: JAWA BARAT | B11: Bandung | C11: 72.39 | D11: 93.95 | E11: 6.91 | F11: 81060.97 | G11: 8.96 | H11: 71.67 | I11: 75.34 | J11: 367403 | K11: 5.07 | L11: 8.58 | M11: 62.2 | N11: 0.414 | O11: 3616540 | Q11: =Z2 -> 0.23498053 | R11: =Z3 -> 0.086230032 | S11: =Z4 -> -0.29591909 | T11: =Z5 -> 0.304137 | U11: =Z6 -> 0.24222831 | V11: =Z7 -> 0.12915119 | W11: =Z8 -> 0.12080251 | X11: =Z9 -> 0.16855083 | Y11: =Z10 -> -0.28630068 | Z11: =CORREL(L$2:L$42,L$2:L$42) -> 1 | AA11: =CORREL(L$2:L$42,M$2:M$42) -> -0.54828036 | AB11: =CORREL(L$2:L$42,N$2:N$42) -> 0.35720927
A12: JAWA BARAT | B12: Garut | C12: 66.12 | D12: 82.29 | E12: 9.98 | F12: 38598.43 | G12: 7.52 | H12: 69.49 | I12: 73.3 | J12: 310437 | K12: 4.06 | L12: 8.95 | M12: 61.11 | N12: 0.352 | O12: 2577350 | Q12: =AA2 -> -0.24657195 | R12: =AA3 -> -0.1165227 | S12: =AA4 -> 0.18782887 | T12: =AA5 -> -0.097335432 | U12: =AA6 -> -0.31799879 | V12: =AA7 -> -0.054708653 | W12: =AA8 -> -0.051207833 | X12: =AA9 -> -0.2310517 | Y12: =AA10 -> 0.23759144 | Z12: =AA11 -> -0.54828036 | AA12: =CORREL(M$2:M$42,M$2:M$42) -> 1 | AB12: =CORREL(M$2:M$42,N$2:N$42) -> -0.31898592
A13: JAWA BARAT | B13: Tasikmalaya | C13: 65.67 | D13: 86.02 | E13: 10.34 | F13: 24344.86 | G13: 7.35 | H13: 67.51 | I13: 71.39 | J13: 323880 | K13: 5.64 | L13: 7.12 | M13: 69.54 | N13: 0.343 | O13: 1861060 | Q13: =AB2 -> 0.53243255 | R13: =AB3 -> 0.36143844 | S13: =AB4 -> -0.27070574 | T13: =AB5 -> 0.40207041 | U13: =AB6 -> 0.55070546 | V13: =AB7 -> 0.57401025 | W13: =AB8 -> 0.57117617 | X13: =AB9 -> 0.27534691 | Y13: =AB10 -> -0.062609456 | Z13: =AB11 -> 0.35720927 | AA13: =AB12 -> -0.31898592 | AB13: =CORREL(N$2:N$42,N$2:N$42) -> 1
A14: JAWA BARAT | B14: Ciamis | C14: 70.49 | D14: 86.61 | E14: 7.62 | F14: 21970.41 | G14: 7.7 | H14: 69.92 | I14: 73.72 | J14: 378108 | K14: 5.11 | L14: 5.66 | M14: 71.41 | N14: 0.336 | O14: 1226050 | Q14: =SUMSQ(Q2:AB13) - 12 -> 32.223948
A15: JAWA BARAT | B15: Kuningan | C15: 69.38 | D15: 86.81 | E15: 12.82 | F15: 16882.76 | G15: 7.57 | H15: 71.72 | I15: 75.42 | J15: 352358 | K15: 3.51 | L15: 11.22 | M15: 61.98 | N15: 0.361 | O15: 1162590
A16: JAWA BARAT | B16: Cirebon | C16: 68.75 | D16: 83.47 | E16: 11.24 | F16: 33304.05 | G16: 6.92 | H16: 70.08 | I16: 73.87 | J16: 393452 | K16: 5.41 | L16: 11.52 | M16: 63.79 | N16: 0.338 | O16: 2270350
A17: JAWA BARAT | B17: Majalengka | C17: 67.59 | D17: 85.91 | E17: 11.43 | F17: 21754.54 | G17: 7.27 | H17: 68.31 | I17: 72.18 | J17: 453201 | K17: 4.17 | L17: 5.84 | M17: 69.66 | N17: 0.336 | O17: 1301570 | Q17: V
A18: JAWA BARAT | B18: Sumedang | C18: 71.64 | D18: 95.18 | E18: 10.26 | F18: 23665.01 | G18: 8.51 | H18: 70.52 | I18: 74.3 | J18: 353092 | K18: 4.01 | L18: 9.89 | M18: 68.96 | N18: 0.384 | O18: 1149470 | Q18: {=MINVERSE(Q2:AB13)} -> 42.066685 | R18: -4.7828527 | S18: 2.8218038 | T18: -3.4009537 | U18: -21.514315 | V18: -24.036656 | W18: 15.570559 | X18: -5.31781 | Y18: 3.5091601 | Z18: 0.79612603 | AA18: -0.17173181 | AB18: -0.44107325
A19: JAWA BARAT | B19: Indramayu | C19: 67.29 | D19: 88.15 | E19: 12.7 | F19: 59200 | G19: 6.3 | H19: 69.72 | I19: 73.52 | J19: 474807 | K19: 4.28 | L19: 9.21 | M19: 69.53 | N19: 0.319 | O19: 1829230 | Q19: -4.7828527 | R19: 2.9109967 | S19: -0.65654592 | T19: 0.094162583 | U19: 0.87681853 | V19: -0.87758338 | W19: 1.9498329 | X19: 0.42554266 | Y19: -0.092901789 | Z19: 0.12103268 | AA19: -0.20474882 | AB19: -0.045549724
A20: JAWA BARAT | B20: Subang | C20: 68.95 | D20: 90.53 | E20: 9.31 | F20: 28344.32 | G20: 7.1 | H20: 70.46 | I20: 74.22 | J20: 351885 | K20: 4.81 | L20: 9.48 | M20: 66.7 | N20: 0.35 | O20: 1605250 | Q20: 2.8218038 | R20: -0.65654592 | S20: 3.4835935 | T20: 0.50372952 | U20: 1.7264402 | V20: 3.6129995 | W20: -4.3014853 | X20: -2.1833101 | Y20: -1.0148952 | Z20: 0.34725532 | AA20: 0.27934938 | AB20: -0.5896868
A21: JAWA BARAT | B21: Purwakarta | C21: 70.82 | D21: 86.56 | E21: 8.27 | F21: 45293.24 | G21: 8.09 | H21: 69.05 | I21: 72.89 | J21: 378287 | K21: 4.08 | L21: 11.07 | M21: 60.91 | N21: 0.414 | O21: 994330 | Q21: -3.4009537 | R21: 0.094162583 | S21: 0.50372952 | T21: 2.3476146 | U21: 3.0215165 | V21: -2.2344201 | W21: 2.6565123 | X21: -0.80147178 | Y21: -0.04616327 | Z21: -0.33244014 | AA21: -0.29470861 | AB21: -0.6869863
A22: JAWA BARAT | B22: Karawang | C22: 70.66 | D22: 90.12 | E22: 8.26 | F22: 157710.59 | G22: 7.77 | H22: 70.25 | I22: 74.03 | J22: 466152 | K22: 3.79 | L22: 11.52 | M22: 64.9 | N22: 0.327 | O22: 2434090 | Q22: -21.514315 | R22: 0.87681853 | S22: 1.7264402 | T22: 3.0215165 | U22: 23.37095 | V22: -19.635353 | W22: 22.218091 | X22: -1.9732475 | Y22: 0.85775478 | Z22: 1.1868149 | AA22: 1.185549 | AB22: -3.3482963
A23: JAWA BARAT | B23: Bekasi | C23: 74.07 | D23: 88.58 | E23: 4.82 | F23: 242971.39 | G23: 9.12 | H23: 71.81 | I23: 75.5 | J23: 518667 | K23: 2.26 | L23: 11.54 | M23: 64.23 | N23: 0.372 | O23: 3101730 | Q23: -24.036656 | R23: -0.87758338 | S23: 3.6129995 | T23: -2.2344201 | U23: -19.635353 | V23: 1273.4878 | W23: -1265.5383 | X23: 32.296675 | Y23: -14.449681 | Z23: -14.018791 | AA23: -1.1031318 | AB23: 12.513413
A24: JAWA BARAT | B24: Bandung Barat | C24: 68.08 | D24: 79.06 | E24: 10.49 | F24: 30640.41 | G24: 8.19 | H24: 70.43 | I24: 74.2 | J24: 362212 | K24: 5.07 | L24: 12.25 | M24: 59.91 | N24: 0.376 | O24: 1782190 | Q24: 15.570559 | R24: 1.9498329 | S24: -4.3014853 | T24: 2.6565123 | U24: 22.218091 | V24: -1265.5383 | W24: 1261.62 | X24: -31.855074 | Y24: 12.307884 | Z24: 13.544685 | AA24: 0.64906656 | AB24: -12.727941
A25: JAWA BARAT | B25: Pangandaran | C25: 68.06 | D25: 89.78 | E25: 8.99 | F25: 7738.97 | G25: 7.74 | H25: 69.49 | I25: 73.29 | J25: 382264 | K25: 4.39 | L25: 5.08 | M25: 76.79 | N25: 0.335 | O25: 422410 | Q25: -5.31781 | R25: 0.42554266 | S25: -2.1833101 | T25: -0.80147178 | U25: -1.9732475 | V25: 32.296675 | W25: -31.855074 | X25: 6.858251 | Y25: 1.3090249 | Z25: -0.24174908 | AA25: 0.19631814 | AB25: 1.4942335
A26: JAWA BARAT | B26: Kota Bogor | C26: 76.11 | D26: 91.02 | E26: 6.68 | F26: 32162.74 | G26: 10.33 | H26: 71.74 | I26: 75.44 | J26: 547399 | K26: 2.95 | L26: 12.68 | M26: 60.81 | N26: 0.412 | O26: 1040570 | Q26: 3.5091601 | R26: -0.092901789 | S26: -1.0148952 | T26: -0.04616327 | U26: 0.85775478 | V26: -14.449681 | W26: 12.307884 | X26: 1.3090249 | Y26: 5.6450055 | Z26: 1.184564 | AA26: 0.23623636 | AB26: -1.6538513
A27: JAWA BARAT | B27: Kota Sukabumi | C27: 74.21 | D27: 91.36 | E27: 7.7 | F27: 8534.72 | G27: 9.59 | H27: 70.52 | I27: 74.28 | J27: 547415 | K27: 3.65 | L27: 12.17 | M27: 55.74 | N27: 0.397 | O27: 344830 | Q27: 0.79612603 | R27: 0.12103268 | S27: 0.34725532 | T27: -0.33244014 | U27: 1.1868149 | V27: -14.018791 | W27: 13.544685 | X27: -0.24174908 | Y27: 1.184564 | Z27: 2.1155742 | AA27: 0.95448007 | AB27: -0.8935255
A28: JAWA BARAT | B28: Kota Bandung | C28: 81.51 | D28: 94.68 | E28: 3.99 | F28: 193144.95 | G28: 10.75 | H28: 72.45 | I28: 75.97 | J28: 500452 | K28: 2.82 | L28: 11.19 | M28: 64.71 | N28: 0.402 | O28: 2438350 | Q28: -0.17173181 | R28: -0.20474882 | S28: 0.27934938 | T28: -0.29470861 | U28: 1.185549 | V28: -1.1031318 | W28: 0.64906656 | X28: 0.19631814 | Y28: 0.23623636 | Z28: 0.95448007 | AA28: 1.7633895 | AB28: 0.15142639
A29: JAWA BARAT | B29: Kota Cirebon | C29: 74.89 | D29: 94.39 | E29: 9.52 | F29: 16648.21 | G29: 9.91 | H29: 70.35 | I29: 74.13 | J29: 457954 | K29: 4.52 | L29: 10.97 | M29: 63.76 | N29: 0.421 | O29: 332580 | Q29: -0.44107325 | R29: -0.045549724 | S29: -0.5896868 | T29: -0.6869863 | U29: -3.3482963 | V29: 12.513413 | W29: -12.727941 | X29: 1.4942335 | Y29: -1.6538513 | Z29: -0.8935255 | AA29: 0.15142639 | AB29: 3.1513837
A30: JAWA BARAT | B30: Kota Bekasi | C30: 81.5 | D30: 92.95 | E30: 4.38 | F30: 67619.24 | G30: 11.16 | H30: 73.22 | I30: 76.71 | J30: 657953 | K30: 1.33 | L30: 10.68 | M30: 64.74 | N30: 0.352 | O30: 2536120
A31: JAWA BARAT | B31: Kota Depok | C31: 80.97 | D31: 93.01 | E31: 2.45 | F31: 48135.93 | G31: 11.28 | H31: 72.61 | I31: 76.42 | J31: 688194 | K31: 1.26 | L31: 9.87 | M31: 63.96 | N31: 0.344 | O31: 2046830
A32: JAWA BARAT | B32: Kota Cimahi | C32: 77.83 | D32: 92.01 | E32: 5.11 | F32: 22340.56 | G32: 10.96 | H32: 72.19 | I32: 75.77 | J32: 511375 | K32: 2.66 | L32: 13.3 | M32: 62.67 | N32: 0.38 | O32: 566170 | Q32: baru
A33: JAWA BARAT | B33: Kota Tasikmalaya | C33: 73.04 | D33: 91.64 | E33: 12.97 | F33: 15430.02 | G33: 9.33 | H33: 70.25 | I33: 74.02 | J33: 470150 | K33: 4.17 | L33: 7.99 | M33: 66.54 | N33: 0.366 | O33: 713670 | Q33: =-(Q18)/SQRT(Q18*Q18) -> -1 | R33: =-(R18)/SQRT(Q18*R19) -> 0.43221218 | S33: =-(S18)/SQRT(Q18*S20) -> -0.23310089 | T33: =-(T18)/SQRT(Q18*T21) -> 0.34223008 | U33: =-(U18)/SQRT(Q18*U22) -> 0.68615178 | V33: =-(V18)/SQRT(Q18*V23) -> 0.10385024 | W33: =-(W18)/SQRT(Q18*W24) -> -0.067588184 | X33: =-(X18)/SQRT(Q18*X25) -> 0.3130812 | Y33: =-(Y18)/SQRT(Q18*Y26) -> -0.22772036 | Z33: =-(Z18)/SQRT(Q18*Z27) -> -0.084391469 | AA33: =-(AA18)/SQRT(Q18*AA28) -> 0.019939189 | AB33: =-(AB18)/SQRT(Q18*AB29) -> 0.038308128
A34: JAWA BARAT | B34: Kota Banjar | C34: 71.7 | D34: 87.17 | E34: 6.09 | F34: 3251.76 | G34: 8.63 | H34: 69.04 | I34: 72.89 | J34: 344363 | K34: 3.93 | L34: 6.73 | M34: 67.35 | N34: 0.312 | O34: 200270 | Q34: =R33 -> 0.43221218 | R34: =-(R19)/SQRT(R19*R19) -> -1 | S34: =-(S19)/SQRT(R19*S20) -> 0.20617239 | T34: =-(T19)/SQRT(R19*T21) -> -0.036020033 | U34: =-(U19)/SQRT(R19*U22) -> -0.10630426 | V34: =-(V19)/SQRT(R19*V23) -> 0.014413523 | W34: =-(W19)/SQRT(R19*W24) -> -0.032174533 | X34: =-(X19)/SQRT(R19*X25) -> -0.09523916 | Y34: =-(Y19)/SQRT(R19*Y26) -> 0.0229177 | Z34: =-(Z19)/SQRT(R19*Z27) -> -0.048771673 | AA34: =-(AA19)/SQRT(R19*AA28) -> 0.090370447 | AB34: =-(AB19)/SQRT(R19*AB29) -> 0.015038837
A35: BANTEN | B35: Pandeglang | C35: 65 | D35: 86.71 | E35: 9.92 | F35: 19511.68 | G35: 7.1 | H35: 62.69 | I35: 66.54 | J35: 361713 | K35: 3.6 | L35: 9.15 | M35: 60.28 | N35: 0.305 | O35: 1270.09 | Q35: =S33 -> -0.23310089 | R35: =S34 -> 0.20617239 | S35: =-(S20)/SQRT(S20*S20) -> -1 | T35: =-(T20)/SQRT(S20*T21) -> -0.17614498 | U35: =-(U20)/SQRT(S20*U22) -> -0.19133729 | V35: =-(V20)/SQRT(S20*V23) -> -0.054244632 | W35: =-(W20)/SQRT(S20*W24) -> 0.06488442 | X35: =-(X20)/SQRT(S20*X25) -> 0.44667844 | Y35: =-(Y20)/SQRT(S20*Y26) -> 0.22886284 | Z35: =-(Z20)/SQRT(S20*Z27) -> -0.12791487 | AA35: =-(AA20)/SQRT(S20*AA28) -> -0.11270933 | AB35: =-(AB20)/SQRT(S20*AB29) -> 0.17797419
A36: BANTEN | B36: Lebak | C36: 63.91 | D36: 79.81 | E36: 9.24 | F36: 20622.04 | G36: 6.4 | H36: 65.19 | I36: 69.13 | J36: 334509 | K36: 3.14 | L36: 9.63 | M36: 69.97 | N36: 0.314 | O36: 1383.54 | Q36: =T33 -> 0.34223008 | R36: =T34 -> -0.036020033 | S36: =T35 -> -0.17614498 | T36: =-(T21)/SQRT(T21*T21) -> -1 | U36: =-(U21)/SQRT(T21*U22) -> -0.40791849 | V36: =-(V21)/SQRT(T21*V23) -> 0.040865237 | W36: =-(W21)/SQRT(T21*W24) -> -0.048812849 | X36: =-(X21)/SQRT(T21*X25) -> 0.19974143 | Y36: =-(Y21)/SQRT(T21*Y26) -> 0.012680927 | Z36: =-(Z21)/SQRT(T21*Z27) -> 0.14917153 | AA36: =-(AA21)/SQRT(T21*AA28) -> 0.1448456 | AB36: =-(AB21)/SQRT(T21*AB29) -> 0.25257132
A37: BANTEN | B37: Tangerang | C37: 71.92 | D37: 90.98 | E37: 6.23 | F37: 93480.39 | G37: 8.39 | H37: 67.86 | I37: 71.81 | J37: 520742 | K37: 1.84 | L37: 13.06 | M37: 65.43 | N37: 0.285 | O37: 3236.7 | Q37: =U33 -> 0.68615178 | R37: =U34 -> -0.10630426 | S37: =U35 -> -0.19133729 | T37: =U36 -> -0.40791849 | U37: =-(U22)/SQRT(U22*U22) -> -1 | V37: =-(V22)/SQRT(U22*V23) -> 0.11381595 | W37: =-(W22)/SQRT(U22*W24) -> -0.12939106 | X37: =-(X22)/SQRT(U22*X25) -> 0.15586073 | Y37: =-(Y22)/SQRT(U22*Y26) -> -0.074678016 | Z37: =-(Z22)/SQRT(U22*Z27) -> -0.16878377 | AA37: =-(AA22)/SQRT(U22*AA28) -> -0.18467462 | AB37: =-(AB22)/SQRT(U22*AB29) -> 0.3901531
A38: BANTEN | B38: Serang | C38: 66.7 | D38: 92.14 | E38: 4.94 | F38: 52866.43 | G38: 7.5 | H38: 62.68 | I38: 66.5 | J38: 341074 | K38: 2.44 | L38: 12.22 | M38: 63.46 | N38: 0.303 | O38: 1618.36 | Q38: =V33 -> 0.10385024 | R38: =V34 -> 0.014413523 | S38: =V35 -> -0.054244632 | T38: =V36 -> 0.040865237 | U38: =V37 -> 0.11381595 | V38: =-(V23)/SQRT(V23*V23) -> -1 | W38: =-(W23)/SQRT(V23*W24) -> 0.99842082 | X38: =-(X23)/SQRT(V23*X25) -> -0.34558408 | Y38: =-(Y23)/SQRT(V23*Y26) -> 0.17042319 | Z38: =-(Z23)/SQRT(V23*Z27) -> 0.27008411 | AA38: =-(AA23)/SQRT(V23*AA28) -> 0.023278548 | AB38: =-(AB23)/SQRT(V23*AB29) -> -0.19752758
A39: BANTEN | B39: Kota Tangerang | C39: 78.25 | D39: 95.06 | E39: 5.22 | F39: 102415.7 | G39: 10.69 | H39: 69.61 | I39: 73.49 | J39: 632835 | K39: 1.42 | L39: 8.63 | M39: 64.97 | N39: 0.339 | O39: 1891.4 | Q39: =W33 -> -0.067588184 | R39: =W34 -> -0.032174533 | S39: =W35 -> 0.06488442 | T39: =W36 -> -0.048812849 | U39: =W37 -> -0.12939106 | V39: =W38 -> 0.99842082 | W39: =-(W24)/SQRT(W24*W24) -> -1 | X39: =-(X24)/SQRT(W24*X25) -> 0.34245827 | Y39: =-(Y24)/SQRT(W24*Y26) -> -0.14584345 | Z39: =-(Z24)/SQRT(W24*Z27) -> -0.26217454 | AA39: =-(AA24)/SQRT(W24*AA28) -> -0.013761027 | AB39: =-(AB24)/SQRT(W24*AB29) -> 0.20185672
A40: BANTEN | B40: Kota Cilegon | C40: 73.05 | D40: 87.22 | E40: 3.69 | F40: 73319.12 | G40: 9.87 | H40: 64.66 | I40: 68.58 | J40: 504571 | K40: 2.02 | L40: 12.69 | M40: 61.83 | N40: 0.373 | O40: 433.76 | Q40: =X33 -> 0.3130812 | R40: =X34 -> -0.09523916 | S40: =X35 -> 0.44667844 | T40: =X36 -> 0.19974143 | U40: =X37 -> 0.15586073 | V40: =X38 -> -0.34558408 | W40: =X39 -> 0.34245827 | X40: =-(X25)/SQRT(X25*X25) -> -1 | Y40: =-(Y25)/SQRT(X25*Y26) -> -0.21038222 | Z40: =-(Z25)/SQRT(X25*Z27) -> 0.063466422 | AA40: =-(AA25)/SQRT(X25*AA28) -> -0.056452038 | AB40: =-(AB25)/SQRT(X25*AB29) -> -0.32141129
...

Sheet Bobot 2020
A1: Provinsi | B1: Kabupaten/Kota | C1: IPM | D1: IPG | E1: PPM | F1: PDRB_ADHK | G1: RLS | H1: AHH_L | I1: AHH_P | J1: GK | K1: PKKP | L1: TPT | M1: TPAK | N1: GR | Q1: RV
A2: DKI JAKARTA | B2: Kep. Seribu | C2: ='2020'!C2*'Bobot M'!$J2 -> 0.034100519 | D2: ='2020'!D2*'Bobot M'!$J2 -> 0.044459688 | E2: ='2020'!E2*'Bobot M'!$J2 -> 0.0070790829 | F2: ='2020'!F2*'Bobot M'!$J2 -> 1.764415 | G2: ='2020'!G2*'Bobot M'!$J2 -> 0.0041322421 | H2: ='2020'!H2*'Bobot M'!$J2 -> 0.031739237 | I2: ='2020'!I2*'Bobot M'!$J2 -> 0.033676821 | J2: ='2020'!J2*'Bobot M'!$J2 -> 315.08441 | ... N2: ='2020'!N2*'Bobot M'!$J2 -> 0.00014567582 | Q2: =CORREL(C$2:C$42,C$2:C$42) -> 1 | R2: =CORREL(C$2:C$42,D$2:D$42) -> 0.99704062 | S2: =CORREL(C$2:C$42,E$2:E$42) -> 0.80419513 | T2: =CORREL(C$2:C$42,F$2:F$42) -> 0.74424211 | U2: =CORREL(C$2:C$42,G$2:G$42) -> 0.98878506 | V2: =CORREL(C$2:C$42,H$2:H$42) -> 0.99530689 | W2: =CORREL(C$2:C$42,I$2:I$42) -> 0.9950606 | X2: =CORREL(C$2:C$42,J$2:J$42) -> 0.96085378 | Y2: =CORREL(C$2:C$42,K$2:K$42) -> 0.8170888 | Z2: =CORREL(C$2:C$42,L$2:L$42) -> 0.95765212 | AA2: =CORREL(C$2:C$42,M$2:M$42) -> 0.98959602 | AB2: =CORREL(C$2:C$42,N$2:N$42) -> 0.99164693
A3: DKI JAKARTA | B3: Kota Jakarta Selatan | C3: ='2020'!C3*'Bobot M'!$J3 -> 3.1992431 | D3: ='2020'!D3*'Bobot M'!$J3 -> 3.6304914 | E3: ='2020'!E3*'Bobot M'!$J3 -> 0.12952554 | F3: ='2020'!F3*'Bobot M'!$J3 -> 15832.22 | G3: ='2020'!G3*'Bobot M'!$J3 -> 0.43917844 | H3: ='2020'!H3*'Bobot M'!$J3 -> 2.7275889 | I3: ='2020'!I3*'Bobot M'!$J3 -> 2.8714642 | J3: ='2020'!J3*'Bobot M'!$J3 -> 29557.918 | ... N3: ='2020'!N3*'Bobot M'!$J3 -> 0.016124608 | Q3: =R2 -> 0.99704062 | R3: =CORREL(D$2:D$42,D$2:D$42) -> 1 | S3: =CORREL(D$2:D$42,E$2:E$42) -> 0.83548087 | T3: =CORREL(D$2:D$42,F$2:F$42) -> 0.7151433 | U3: =CORREL(D$2:D$42,G$2:G$42) -> 0.9767906 | V3: =CORREL(D$2:D$42,H$2:H$42) -> 0.99855774 | W3: =CORREL(D$2:D$42,I$2:I$42) -> 0.99849503 | X3: =CORREL(D$2:D$42,J$2:J$42) -> 0.94157599 | Y3: =CORREL(D$2:D$42,K$2:K$42) -> 0.85288784 | Z3: =CORREL(D$2:D$42,L$2:L$42) -> 0.96125492 | AA3: =CORREL(D$2:D$42,M$2:M$42) -> 0.99542407 | AB3: =CORREL(D$2:D$42,N$2:N$42) -> 0.99509453
A4: DKI JAKARTA | B4: Kota Jakarta Timur | C4: ='2020'!C4*'Bobot M'!$J4 -> 4.2791699 | D4: ='2020'!D4*'Bobot M'!$J4 -> 4.9428399 | E4: ='2020'!E4*'Bobot M'!$J4 -> 0.21535624 | F4: ='2020'!F4*'Bobot M'!$J4 -> 15505.399 | G4: ='2020'!G4*'Bobot M'!$J4 -> 0.6036187 | H4: ='2020'!H4*'Bobot M'!$J4 -> 3.7583806 | I4: ='2020'!I4*'Bobot M'!$J4 -> 3.9457819 | J4: ='2020'!J4*'Bobot M'!$J4 -> 30126.785 | ... N4: ='2020'!N4*'Bobot M'!$J4 -> 0.018791903 | Q4: =S2 -> 0.80419513 | R4: =S3 -> 0.83548087 | S4: =CORREL(E$2:E$42,E$2:E$42) -> 1 | T4: =CORREL(E$2:E$42,F$2:F$42) -> 0.35769729 | U4: =CORREL(E$2:E$42,G$2:G$42) -> 0.71760498 | V4: =CORREL(E$2:E$42,H$2:H$42) -> 0.85154281 | W4: =CORREL(E$2:E$42,I$2:I$42) -> 0.85287114 | X4: =CORREL(E$2:E$42,J$2:J$42) -> 0.66064628 | Y4: =CORREL(E$2:E$42,K$2:K$42) -> 0.94897572 | Z4: =CORREL(E$2:E$42,L$2:L$42) -> 0.83052659 | AA4: =CORREL(E$2:E$42,M$2:M$42) -> 0.87039661 | AB4: =CORREL(E$2:E$42,N$2:N$42) -> 0.8371468
A5: DKI JAKARTA | B5: Kota Jakarta Pusat | C5: ='2020'!C5*'Bobot M'!$J5 -> 1.441227 | D5: ='2020'!D5*'Bobot M'!$J5 -> 1.6999361 | E5: ='2020'!E5*'Bobot M'!$J5 -> 0.07986158 | F5: ='2020'!F5*'Bobot M'!$J5 -> 7959.9177 | G5: ='2020'!G5*'Bobot M'!$J5 -> 0.20151325 | H5: ='2020'!H5*'Bobot M'!$J5 -> 1.2788477 | I5: ='2020'!I5*'Bobot M'!$J5 -> 1.3443661 | J5: ='2020'!J5*'Bobot M'!$J5 -> 11905.361 | ... N5: ='2020'!N5*'Bobot M'!$J5 -> 0.0069059903 | Q5: =T2 -> 0.74424211 | R5: =T3 -> 0.7151433 | S5: =T4 -> 0.35769729 | T5: =CORREL(F$2:F$42,F$2:F$42) -> 1 | U5: =CORREL(F$2:F$42,G$2:G$42) -> 0.79056414 | V5: =CORREL(F$2:F$42,H$2:H$42) -> 0.69601472 | W5: =CORREL(F$2:F$42,I$2:I$42) -> 0.69513412 | X5: =CORREL(F$2:F$42,J$2:J$42) -> 0.81921085 | Y5: =CORREL(F$2:F$42,K$2:K$42) -> 0.36298173 | Z5: =CORREL(F$2:F$42,L$2:L$42) -> 0.7097933 | AA5: =CORREL(F$2:F$42,M$2:M$42) -> 0.67832811 | AB5: =CORREL(F$2:F$42,N$2:N$42) -> 0.71761134
A6: DKI JAKARTA | B6: Kota Jakarta Barat | C6: ='2020'!C6*'Bobot M'!$J6 -> 3.3660435 | D6: ='2020'!D6*'Bobot M'!$J6 -> 3.9360125 | E6: ='2020'!E6*'Bobot M'!$J6 -> 0.1757887 | F6: ='2020'!F6*'Bobot M'!$J6 -> 13077.547 | G6: ='2020'!G6*'Bobot M'!$J6 -> 0.43967857 | H6: ='2020'!H6*'Bobot M'!$J6 -> 2.9664861 | I6: ='2020'!I6*'Bobot M'!$J6 -> 3.1199393 | J6: ='2020'!J6*'Bobot M'!$J6 -> 23071.874 | ... N6: ='2020'!N6*'Bobot M'!$J6 -> 0.015717578 | Q6: =U2 -> 0.98878506 | R6: =U3 -> 0.9767906 | S6: =U4 -> 0.71760498 | T6: =U5 -> 0.79056414 | U6: =CORREL(G$2:G$42,G$2:G$42) -> 1 | V6: =CORREL(G$2:G$42,H$2:H$42) -> 0.97118772 | W6: =CORREL(G$2:G$42,I$2:I$42) -> 0.97055602 | X6: =CORREL(G$2:G$42,J$2:J$42) -> 0.97738754 | Y6: =CORREL(G$2:G$42,K$2:K$42) -> 0.73649492 | Z6: =CORREL(G$2:G$42,L$2:L$42) -> 0.93025501 | AA6: =CORREL(G$2:G$42,M$2:M$42) -> 0.95943609 | AB6: =CORREL(G$2:G$42,N$2:N$42) -> 0.97217701
A7: DKI JAKARTA | B7: Kota Jakarta Utara | C7: ='2020'!C7*'Bobot M'!$J7 -> 2.4188444 | D7: ='2020'!D7*'Bobot M'!$J7 -> 2.8177172 | E7: ='2020'!E7*'Bobot M'!$J7 -> 0.20425663 | F7: ='2020'!F7*'Bobot M'!$J7 -> 9402.4503 | G7: ='2020'!G7*'Bobot M'!$J7 -> 0.32536455 | H7: ='2020'!H7*'Bobot M'!$J7 -> 2.1498161 | I7: ='2020'!I7*'Bobot M'!$J7 -> 2.2633924 | J7: ='2020'!J7*'Bobot M'!$J7 -> 17902.28 | ... N7: ='2020'!N7*'Bobot M'!$J7 -> 0.012442181 | Q7: =V2 -> 0.99530689 | R7: =V3 -> 0.99855774 | S7: =V4 -> 0.85154281 | T7: =V5 -> 0.69601472 | U7: =V6 -> 0.97118772 | V7: =CORREL(H$2:H$42,H$2:H$42) -> 1 | W7: =CORREL(H$2:H$42,I$2:I$42) -> 0.99999346 | X7: =CORREL(H$2:H$42,J$2:J$42) -> 0.93532683 | Y7: =CORREL(H$2:H$42,K$2:K$42) -> 0.86319063 | Z7: =CORREL(H$2:H$42,L$2:L$42) -> 0.96292382 | AA7: =CORREL(H$2:H$42,M$2:M$42) -> 0.99719637 | AB7: =CORREL(H$2:H$42,N$2:N$42) -> 0.99427929
A8: JAWA BARAT | B8: Bogor | C8: ='2020'!C8*'Bobot M'!$J8 -> 6.5081971 | D8: ='2020'!D8*'Bobot M'!$J8 -> 8.2489549 | E8: ='2020'!E8*'Bobot M'!$J8 -> 0.71090959 | F8: ='2020'!F8*'Bobot M'!$J8 -> 14247.183 | G8: ='2020'!G8*'Bobot M'!$J8 -> 0.76730164 | H8: ='2020'!H8*'Bobot M'!$J8 -> 6.4009597 | I8: ='2020'!I8*'Bobot M'!$J8 -> 6.7541034 | J8: ='2020'!J8*'Bobot M'!$J8 -> 37244.36 | ... N8: ='2020'!N8*'Bobot M'!$J8 -> 0.035221919 | Q8: =W2 -> 0.9950606 | R8: =W3 -> 0.99849503 | S8: =W4 -> 0.85287114 | T8: =W5 -> 0.69513412 | U8: =W6 -> 0.97055602 | V8: =W7 -> 0.99999346 | W8: =CORREL(I$2:I$42,I$2:I$42) -> 1 | X8: =CORREL(I$2:I$42,J$2:J$42) -> 0.93462309 | Y8: =CORREL(I$2:I$42,K$2:K$42) -> 0.86438155 | Z8: =CORREL(I$2:I$42,L$2:L$42) -> 0.9632059 | AA8: =CORREL(I$2:I$42,M$2:M$42) -> 0.99734478 | AB8: =CORREL(I$2:I$42,N$2:N$42) -> 0.99425802
A9: JAWA BARAT | B9: Sukabumi | C9: ='2020'!C9*'Bobot M'!$J9 -> 3.0896886 | D9: ='2020'!D9*'Bobot M'!$J9 -> 4.0362753 | E9: ='2020'!E9*'Bobot M'!$J9 -> 0.32754025 | F9: ='2020'!F9*'Bobot M'!$J9 -> 2134.5683 | G9: ='2020'!G9*'Bobot M'!$J9 -> 0.3266163 | H9: ='2020'!H9*'Bobot M'!$J9 -> 3.1890132 | I9: ='2020'!I9*'Bobot M'!$J9 -> 3.3664116 | J9: ='2020'!J9*'Bobot M'!$J9 -> 15165.899 | ... N9: ='2020'!N9*'Bobot M'!$J9 -> 0.015429964 | Q9: =X2 -> 0.96085378 | R9: =X3 -> 0.94157599 | S9: =X4 -> 0.66064628 | T9: =X5 -> 0.81921085 | U9: =X6 -> 0.97738754 | V9: =X7 -> 0.93532683 | W9: =X8 -> 0.93462309 | X9: =CORREL(J$2:J$42,J$2:J$42) -> 1 | Y9: =CORREL(J$2:J$42,K$2:K$42) -> 0.64683112 | Z9: =CORREL(J$2:J$42,L$2:L$42) -> 0.89928601 | AA9: =CORREL(J$2:J$42,M$2:M$42) -> 0.9263061 | AB9: =CORREL(J$2:J$42,N$2:N$42) -> 0.92916172
A10: JAWA BARAT | B10: Cianjur | C10: ='2020'!C10*'Bobot M'!$J10 -> 2.7522204 | D10: ='2020'!D10*'Bobot M'!$J10 -> 3.5430206 | E10: ='2020'!E10*'Bobot M'!$J10 -> 0.43624546 | F10: ='2020'!F10*'Bobot M'!$J10 -> 1338.7312 | G10: ='2020'!G10*'Bobot M'!$J10 -> 0.30234 | H10: ='2020'!H10*'Bobot M'!$J10 -> 2.8705457 | I10: ='2020'!I10*'Bobot M'!$J10 -> 3.033085 | J10: ='2020'!J10*'Bobot M'!$J10 -> 15651.738 | ... N10: ='2020'!N10*'Bobot M'!$J10 -> 0.014738022 | Q10: =Y2 -> 0.8170888 | R10: =Y3 -> 0.85288784 | S10: =Y4 -> 0.94897572 | T10: =Y5 -> 0.36298173 | U10: =Y6 -> 0.73649492 | V10: =Y7 -> 0.86319063 | W10: =Y8 -> 0.86438155 | X10: =Y9 -> 0.64683112 | Y10: =CORREL(K$2:K$42,K$2:K$42) -> 1 | Z10: =CORREL(K$2:K$42,L$2:L$42) -> 0.8275468 | AA10: =CORREL(K$2:K$42,M$2:M$42) -> 0.87518736 | AB10: =CORREL(K$2:K$42,N$2:N$42) -> 0.86099427
A11: JAWA BARAT | B11: Bandung | C11: ='2020'!C11*'Bobot M'!$J11 -> 4.4431981 | D11: ='2020'!D11*'Bobot M'!$J11 -> 5.7665211 | E11: ='2020'!E11*'Bobot M'!$J11 -> 0.42412625 | F11: ='2020'!F11*'Bobot M'!$J11 -> 4975.4103 | G11: ='2020'!G11*'Bobot M'!$J11 -> 0.54995242 | H11: ='2020'!H11*'Bobot M'!$J11 -> 4.3990055 | I11: ='2020'!I11*'Bobot M'!$J11 -> 4.6242651 | J11: ='2020'!J11*'Bobot M'!$J11 -> 22550.688 | ... N11: ='2020'!N11*'Bobot M'!$J11 -> 0.025410748 | Q11: =Z2 -> 0.95765212 | R11: =Z3 -> 0.96125492 | S11: =Z4 -> 0.83052659 | T11: =Z5 -> 0.7097933 | U11: =Z6 -> 0.93025501 | V11: =Z7 -> 0.96292382 | W11: =Z8 -> 0.9632059 | X11: =Z9 -> 0.89928601 | Y11: =Z10 -> 0.8275468 | Z11: =CORREL(L$2:L$42,L$2:L$42) -> 1 | AA11: =CORREL(L$2:L$42,M$2:M$42) -> 0.95923256 | AB11: =CORREL(L$2:L$42,N$2:N$42) -> 0.96502985
A12: JAWA BARAT | B12: Garut | C12: ='2020'!C12*'Bobot M'!$J12 -> 2.9155297 | D12: ='2020'!D12*'Bobot M'!$J12 -> 3.628538 | E12: ='2020'!E12*'Bobot M'!$J12 -> 0.44006331 | F12: ='2020'!F12*'Bobot M'!$J12 -> 1701.9792 | G12: ='2020'!G12*'Bobot M'!$J12 -> 0.33159079 | H12: ='2020'!H12*'Bobot M'!$J12 -> 3.0641282 | I12: ='2020'!I12*'Bobot M'!$J12 -> 3.2321283 | J12: ='2020'!J12*'Bobot M'!$J12 -> 13688.57 | ... N12: ='2020'!N12*'Bobot M'!$J12 -> 0.015521271 | Q12: =AA2 -> 0.98959602 | R12: =AA3 -> 0.99542407 | S12: =AA4 -> 0.87039661 | T12: =AA5 -> 0.67832811 | U12: =AA6 -> 0.95943609 | V12: =AA7 -> 0.99719637 | W12: =AA8 -> 0.99734478 | X12: =AA9 -> 0.9263061 | Y12: =AA10 -> 0.87518736 | Z12: =AA11 -> 0.95923256 | AA12: =CORREL(M$2:M$42,M$2:M$42) -> 1 | AB12: =CORREL(M$2:M$42,N$2:N$42) -> 0.98945737
A13: JAWA BARAT | B13: Tasikmalaya | C13: ='2020'!C13*'Bobot M'!$J13 -> 2.0684957 | D13: ='2020'!D13*'Bobot M'!$J13 -> 2.7094869 | E13: ='2020'!E13*'Bobot M'!$J13 -> 0.32569279 | F13: ='2020'!F13*'Bobot M'!$J13 -> 766.82258 | G13: ='2020'!G13*'Bobot M'!$J13 -> 0.23151277 | H13: ='2020'!H13*'Bobot M'!$J13 -> 2.1264527 | I13: ='2020'!I13*'Bobot M'!$J13 -> 2.2486662 | J13: ='2020'!J13*'Bobot M'!$J13 -> 10201.681 | ... N13: ='2020'!N13*'Bobot M'!$J13 -> 0.010803929 | Q13: =AB2 -> 0.99164693 | R13: =AB3 -> 0.99509453 | S13: =AB4 -> 0.8371468 | T13: =AB5 -> 0.71761134 | U13: =AB6 -> 0.97217701 | V13: =AB7 -> 0.99427929 | W13: =AB8 -> 0.99425802 | X13: =AB9 -> 0.92916172 | Y13: =AB10 -> 0.86099427 | Z13: =AB11 -> 0.96502985 | AA13: =AB12 -> 0.98945737 | AB13: =CORREL(N$2:N$42,N$2:N$42) -> 1
A14: JAWA BARAT | B14: Ciamis | C14: ='2020'!C14*'Bobot M'!$J14 -> 1.4589769 | D14: ='2020'!D14*'Bobot M'!$J14 -> 1.7926229 | E14: ='2020'!E14*'Bobot M'!$J14 -> 0.15771605 | F14: ='2020'!F14*'Bobot M'!$J14 -> 454.73572 | G14: ='2020'!G14*'Bobot M'!$J14 -> 0.15937186 | H14: ='2020'!H14*'Bobot M'!$J14 -> 1.4471793 | I14: ='2020'!I14*'Bobot M'!$J14 -> 1.5258303 | J14: ='2020'!J14*'Bobot M'!$J14 -> 7825.9447 | ... N14: ='2020'!N14*'Bobot M'!$J14 -> 0.0069544083 | Q14: =SUMSQ(Q2:AB13) - 12 -> 103.80473
A15: JAWA BARAT | B15: Kuningan | C15: ='2020'!C15*'Bobot M'!$J15 -> 1.3732178 | D15: ='2020'!D15*'Bobot M'!$J15 -> 1.7182047 | E15: ='2020'!E15*'Bobot M'!$J15 -> 0.25374247 | F15: ='2020'!F15*'Bobot M'!$J15 -> 334.15548 | G15: ='2020'!G15*'Bobot M'!$J15 -> 0.14983077 | H15: ='2020'!H15*'Bobot M'!$J15 -> 1.4195328 | I15: ='2020'!I15*'Bobot M'!$J15 -> 1.4927658 | J15: ='2020'!J15*'Bobot M'!$J15 -> 6974.1178 | ... N15: ='2020'!N15*'Bobot M'!$J15 -> 0.0071451663
A16: JAWA BARAT | B16: Cirebon | C16: ='2020'!C16*'Bobot M'!$J16 -> 2.6676827 | D16: ='2020'!D16*'Bobot M'!$J16 -> 3.2388579 | E16: ='2020'!E16*'Bobot M'!$J16 -> 0.43614187 | F16: ='2020'!F16*'Bobot M'!$J16 -> 1292.2857 | G16: ='2020'!G16*'Bobot M'!$J16 -> 0.26851439 | H16: ='2020'!H16*'Bobot M'!$J16 -> 2.7192903 | I16: ='2020'!I16*'Bobot M'!$J16 -> 2.8663523 | J16: ='2020'!J16*'Bobot M'!$J16 -> 15266.983 | ... N16: ='2020'!N16*'Bobot M'!$J16 -> 0.013115298
A17: JAWA BARAT | B17: Majalengka | C17: ='2020'!C17*'Bobot M'!$J17 -> 1.4941191 | D17: ='2020'!D17*'Bobot M'!$J17 -> 1.8990941 | E17: ='2020'!E17*'Bobot M'!$J17 -> 0.25266727 | F17: ='2020'!F17*'Bobot M'!$J17 -> 480.89766 | G17: ='2020'!G17*'Bobot M'!$J17 -> 0.16070788 | H17: ='2020'!H17*'Bobot M'!$J17 -> 1.5100351 | I17: ='2020'!I17*'Bobot M'!$J17 -> 1.5955839 | J17: ='2020'!J17*'Bobot M'!$J17 -> 10018.291 | ... N17: ='2020'!N17*'Bobot M'!$J17 -> 0.0074274894 | Q17: V
A18: JAWA BARAT | B18: Sumedang | C18: ='2020'!C18*'Bobot M'!$J18 -> 1.3940196 | D18: ='2020'!D18*'Bobot M'!$J18 -> 1.8520768 | E18: ='2020'!E18*'Bobot M'!$J18 -> 0.19964602 | F18: ='2020'!F18*'Bobot M'!$J18 -> 460.48977 | G18: ='2020'!G18*'Bobot M'!$J18 -> 0.16559334 | H18: ='2020'!H18*'Bobot M'!$J18 -> 1.3722259 | I18: ='2020'!I18*'Bobot M'!$J18 -> 1.4457797 | J18: ='2020'!J18*'Bobot M'!$J18 -> 6870.703 | ... N18: ='2020'!N18*'Bobot M'!$J18 -> 0.0074721318 | Q18: {=MINVERSE(Q2:AB13)} -> 3530.884 | R18: -732.93107 | S18: 0.024790203 | T18: -62.813708 | U18: -976.00944 | V18: -10932.932 | W18: 9458.4515 | X18: -216.58349 | Y18: -63.679157 | Z18: -70.550262 | AA18: -224.97711 | AB18: 234.85747
A19: JAWA BARAT | B19: Indramayu | C19: ='2020'!C19*'Bobot M'!$J19 -> 2.0981421 | D19: ='2020'!D19*'Bobot M'!$J19 -> 2.7485693 | E19: ='2020'!E19*'Bobot M'!$J19 -> 0.39599353 | F19: ='2020'!F19*'Bobot M'!$J19 -> 1845.8911 | G19: ='2020'!G19*'Bobot M'!$J19 -> 0.19643774 | H19: ='2020'!H19*'Bobot M'!$J19 -> 2.1739109 | I19: ='2020'!I19*'Bobot M'!$J19 -> 2.2923972 | J19: ='2020'!J19*'Bobot M'!$J19 -> 14804.764 | ... N19: ='2020'!N19*'Bobot M'!$J19 -> 0.0099466092 | Q19: -732.93107 | R19: 925.40058 | S19: 41.08845 | T19: -3.2805759 | U19: 106.92117 | V19: 1104.7346 | W19: -1184.2401 | X19: 41.288708 | Y19: -40.549639 | Z19: 10.363197 | AA19: -168.90995 | AB19: -97.338361
A20: JAWA BARAT | B20: Subang | C20: ='2020'!C20*'Bobot M'!$J20 -> 1.8770542 | D20: ='2020'!D20*'Bobot M'!$J20 -> 2.4645354 | E20: ='2020'!E20*'Bobot M'!$J20 -> 0.25344996 | F20: ='2020'!F20*'Bobot M'!$J20 -> 771.62907 | G20: ='2020'!G20*'Bobot M'!$J20 -> 0.19328622 | H20: ='2020'!H20*'Bobot M'!$J20 -> 1.9181615 | I20: ='2020'!I20*'Bobot M'!$J20 -> 2.0205216 | J20: ='2020'!J20*'Bobot M'!$J20 -> 9579.51 | ... N20: ='2020'!N20*'Bobot M'!$J20 -> 0.0095281938 | Q20: 0.024790203 | R20: 41.08845 | S20: 20.897994 | T20: 0.34000765 | U20: 16.706167 | V20: 72.742798 | W20: -105.09123 | X20: -2.7761907 | Y20: -8.7517627 | Z20: -2.0847419 | AA20: -28.052898 | AB20: -2.8466382
A21: JAWA BARAT | B21: Purwakarta | C21: ='2020'!C21*'Bobot M'!$J21 -> 1.2061068 | D21: ='2020'!D21*'Bobot M'!$J21 -> 1.4741684 | E21: ='2020'!E21*'Bobot M'!$J21 -> 0.14084303 | F21: ='2020'!F21*'Bobot M'!$J21 -> 771.37089 | G21: ='2020'!G21*'Bobot M'!$J21 -> 0.13777752 | H21: ='2020'!H21*'Bobot M'!$J21 -> 1.1759627 | I21: ='2020'!I21*'Bobot M'!$J21 -> 1.2413602 | J21: ='2020'!J21*'Bobot M'!$J21 -> 6442.4532 | ... N21: ='2020'!N21*'Bobot M'!$J21 -> 0.0070506669 | Q21: -62.813708 | R21: -3.2805759 | S21: 0.34000765 | T21: 6.5387775 | U21: 18.426419 | V21: 437.70697 | W21: -395.40532 | X21: 1.0001342 | Y21: 4.8420195 | Z21: 0.32442654 | AA21: 8.654029 | AB21: -13.379348
A22: JAWA BARAT | B22: Karawang | C22: ='2020'!C22*'Bobot M'!$J22 -> 2.9358839 | D22: ='2020'!D22*'Bobot M'!$J22 -> 3.7444361 | E22: ='2020'!E22*'Bobot M'!$J22 -> 0.34319843 | F22: ='2020'!F22*'Bobot M'!$J22 -> 6552.7877 | G22: ='2020'!G22*'Bobot M'!$J22 -> 0.3228392 | H22: ='2020'!H22*'Bobot M'!$J22 -> 2.9188486 | I22: ='2020'!I22*'Bobot M'!$J22 -> 3.0759055 | J22: ='2020'!J22*'Bobot M'!$J22 -> 19368.358 | ... N22: ='2020'!N22*'Bobot M'!$J22 -> 0.013586669 | Q22: -976.00944 | R22: 106.92117 | S22: 16.706167 | T22: 18.426419 | U22: 454.41112 | V22: 1493.4668 | W22: -1163.2792 | X22: 25.368273 | Y22: 44.269174 | Z22: 32.840066 | AA22: 118.32215 | AB22: -146.293
A23: JAWA BARAT | B23: Bekasi | C23: ='2020'!C23*'Bobot M'!$J23 -> 3.9358393 | D23: ='2020'!D23*'Bobot M'!$J23 -> 4.7068536 | E23: ='2020'!E23*'Bobot M'!$J23 -> 0.25611915 | F23: ='2020'!F23*'Bobot M'!$J23 -> 12910.711 | G23: ='2020'!G23*'Bobot M'!$J23 -> 0.48460719 | H23: ='2020'!H23*'Bobot M'!$J23 -> 3.8157502 | I23: ='2020'!I23*'Bobot M'!$J23 -> 4.0118248 | J23: ='2020'!J23*'Bobot M'!$J23 -> 27560.28 | ... N23: ='2020'!N23*'Bobot M'!$J23 -> 0.019766872 | Q23: -10932.932 | R23: 1104.7346 | S23: 72.742798 | T23: 437.70697 | U23: 1493.4668 | V23: 282587.45 | W23: -280909.96 | X23: 1172.0293 | Y23: 1031.2159 | Z23: 1038.8378 | AA23: 3953.0386 | AB23: -649.23284
A24: JAWA BARAT | B24: Bandung Barat | C24: ='2020'!C24*'Bobot M'!$J24 -> 2.0787763 | D24: ='2020'!D24*'Bobot M'!$J24 -> 2.4140431 | E24: ='2020'!E24*'Bobot M'!$J24 -> 0.32030499 | F24: ='2020'!F24*'Bobot M'!$J24 -> 935.584 | G24: ='2020'!G24*'Bobot M'!$J24 -> 0.25007606 | H24: ='2020'!H24*'Bobot M'!$J24 -> 2.150532 | I24: ='2020'!I24*'Bobot M'!$J24 -> 2.2656463 | J24: ='2020'!J24*'Bobot M'!$J24 -> 11059.896 | ... N24: ='2020'!N24*'Bobot M'!$J24 -> 0.011480903 | Q24: 9458.4515 | R24: -1184.2401 | S24: -105.09123 | T24: -395.40532 | U24: -1163.2792 | V24: -280909.96 | W24: 280684.1 | X24: -1095.7603 | Y24: -1022.7591 | Z24: -1048.5114 | AA24: -4111.3099 | AB24: 510.7018
A25: JAWA BARAT | B25: Pangandaran | C25: ='2020'!C25*'Bobot M'!$J25 -> 0.48554079 | D25: ='2020'!D25*'Bobot M'!$J25 -> 0.64049151 | E25: ='2020'!E25*'Bobot M'!$J25 -> 0.064134759 | F25: ='2020'!F25*'Bobot M'!$J25 -> 55.209897 | G25: ='2020'!G25*'Bobot M'!$J25 -> 0.055217246 | H25: ='2020'!H25*'Bobot M'!$J25 -> 0.49574243 | I25: ='2020'!I25*'Bobot M'!$J25 -> 0.52285167 | J25: ='2020'!J25*'Bobot M'!$J25 -> 2727.0756 | ... N25: ='2020'!N25*'Bobot M'!$J25 -> 0.0023898937 | Q25: -216.58349 | R25: 41.288708 | S25: -2.7761907 | T25: 1.0001342 | U25: 25.368273 | V25: 1172.0293 | W25: -1095.7603 | X25: 68.97532 | Y25: 28.971695 | Z25: 6.2931976 | AA25: -20.579543 | AB25: 0.03187011
A26: JAWA BARAT | B26: Kota Bogor | C26: ='2020'!C26*'Bobot M'!$J26 -> 1.343762 | D26: ='2020'!D26*'Bobot M'!$J26 -> 1.6070059 | E26: ='2020'!E26*'Bobot M'!$J26 -> 0.11793891 | F26: ='2020'!F26*'Bobot M'!$J26 -> 567.85006 | G26: ='2020'!G26*'Bobot M'!$J26 -> 0.18238157 | H26: ='2020'!H26*'Bobot M'!$J26 -> 1.2666074 | I26: ='2020'!I26*'Bobot M'!$J26 -> 1.3319328 | J26: ='2020'!J26*'Bobot M'!$J26 -> 9664.6168 | ... N26: ='2020'!N26*'Bobot M'!$J26 -> 0.0072740763 | Q26: -63.679157 | R26: -40.549639 | S26: -8.7517627 | T26: 4.8420195 | U26: 44.269174 | V26: 1031.2159 | W26: -1022.7591 | X26: 28.971695 | Y26: 44.116544 | Z26: 11.923096 | AA26: 18.4109 | AB26: -38.744276
A27: JAWA BARAT | B27: Kota Sukabumi | C27: ='2020'!C27*'Bobot M'!$J27 -> 0.43911468 | D27: ='2020'!D27*'Bobot M'!$J27 -> 0.5405945 | E27: ='2020'!E27*'Bobot M'!$J27 -> 0.045562365 | F27: ='2020'!F27*'Bobot M'!$J27 -> 50.501562 | G27: ='2020'!G27*'Bobot M'!$J27 -> 0.056745854 | H27: ='2020'!H27*'Bobot M'!$J27 -> 0.41728025 | I27: ='2020'!I27*'Bobot M'!$J27 -> 0.43952889 | J27: ='2020'!J27*'Bobot M'!$J27 -> 3239.1587 | ... N27: ='2020'!N27*'Bobot M'!$J27 -> 0.0023491245 | Q27: -70.550262 | R27: 10.363197 | S27: -2.0847419 | T27: 0.32442654 | U27: 32.840066 | V27: 1038.8378 | W27: -1048.5114 | X27: 6.2931976 | Y27: 11.923096 | Z27: 23.285242 | AA27: 25.976098 | AB27: -25.455675
A28: JAWA BARAT | B28: Kota Bandung | C28: ='2020'!C28*'Bobot M'!$J28 -> 3.3710706 | D28: ='2020'!D28*'Bobot M'!$J28 -> 3.9157523 | E28: ='2020'!E28*'Bobot M'!$J28 -> 0.16501744 | F28: ='2020'!F28*'Bobot M'!$J28 -> 7988.0416 | G28: ='2020'!G28*'Bobot M'!$J28 -> 0.44459587 | H28: ='2020'!H28*'Bobot M'!$J28 -> 2.9963694 | I28: ='2020'!I28*'Bobot M'!$J28 -> 3.1419487 | J28: ='2020'!J28*'Bobot M'!$J28 -> 20697.571 | ... N28: ='2020'!N28*'Bobot M'!$J28 -> 0.016625818 | Q28: -224.97711 | R28: -168.90995 | S28: -28.052898 | T28: 8.654029 | U28: 118.32215 | V28: 3953.0386 | W28: -4111.3099 | X28: -20.579543 | Y28: 18.4109 | Z28: 25.976098 | AA28: 423.66801 | AB28: 9.7027588
A29: JAWA BARAT | B29: Kota Cirebon | C29: ='2020'!C29*'Bobot M'!$J29 -> 0.42253251 | D29: ='2020'!D29*'Bobot M'!$J29 -> 0.53255232 | E29: ='2020'!E29*'Bobot M'!$J29 -> 0.053712237 | F29: ='2020'!F29*'Bobot M'!$J29 -> 93.929896 | G29: ='2020'!G29*'Bobot M'!$J29 -> 0.055912634 | H29: ='2020'!H29*'Bobot M'!$J29 -> 0.39691764 | I29: ='2020'!I29*'Bobot M'!$J29 -> 0.41824455 | J29: ='2020'!J29*'Bobot M'!$J29 -> 2583.7956 | ... N29: ='2020'!N29*'Bobot M'!$J29 -> 0.0023752996 | Q29: 234.85747 | R29: -97.338361 | S29: -2.8466382 | T29: -13.379348 | U29: -146.293 | V29: -649.23284 | W29: 510.7018 | X29: 0.03187011 | Y29: -38.744276 | Z29: -25.455675 | AA29: 9.7027588 | AB29: 205.2155
A30: JAWA BARAT | B30: Kota Bekasi | C30: ='2020'!C30*'Bobot M'!$J30 -> 3.5212428 | D30: ='2020'!D30*'Bobot M'!$J30 -> 4.015945 | E30: ='2020'!E30*'Bobot M'!$J30 -> 0.1892398 | F30: ='2020'!F30*'Bobot M'!$J30 -> 2921.5185 | G30: ='2020'!G30*'Bobot M'!$J30 -> 0.48217263 | H30: ='2020'!H30*'Bobot M'!$J30 -> 3.1635018 | I30: ='2020'!I30*'Bobot M'!$J30 -> 3.3142887 | J30: ='2020'!J30*'Bobot M'!$J30 -> 28427.144 | ... N30: ='2020'!N30*'Bobot M'!$J30 -> 0.015208312
A31: JAWA BARAT | B31: Kota Depok | C31: ='2020'!C31*'Bobot M'!$J31 -> 2.8450113 | D31: ='2020'!D31*'Bobot M'!$J31 -> 3.2680561 | E31: ='2020'!E31*'Bobot M'!$J31 -> 0.086084694 | F31: ='2020'!F31*'Bobot M'!$J31 -> 1691.3334 | G31: ='2020'!G31*'Bobot M'!$J31 -> 0.39634096 | H31: ='2020'!H31*'Bobot M'!$J31 -> 2.5512692 | I31: ='2020'!I31*'Bobot M'!$J31 -> 2.6851397 | J31: ='2020'!J31*'Bobot M'!$J31 -> 24180.804 | ... N31: ='2020'!N31*'Bobot M'!$J31 -> 0.012086994
A32: JAWA BARAT | B32: Kota Cimahi | C32: ='2020'!C32*'Bobot M'!$J32 -> 0.7549742 | D32: ='2020'!D32*'Bobot M'!$J32 -> 0.89252443 | E32: ='2020'!E32*'Bobot M'!$J32 -> 0.049568524 | F32: ='2020'!F32*'Bobot M'!$J32 -> 216.71009 | G32: ='2020'!G32*'Bobot M'!$J32 -> 0.10631527 | H32: ='2020'!H32*'Bobot M'!$J32 -> 0.70026452 | I32: ='2020'!I32*'Bobot M'!$J32 -> 0.73499159 | J32: ='2020'!J32*'Bobot M'!$J32 -> 4960.49 | ... N32: ='2020'!N32*'Bobot M'!$J32 -> 0.0036861133 | Q32: baru
A33: JAWA BARAT | B33: Kota Tasikmalaya | C33: ='2020'!C33*'Bobot M'!$J33 -> 0.89069731 | D33: ='2020'!D33*'Bobot M'!$J33 -> 1.1175178 | E33: ='2020'!E33*'Bobot M'!$J33 -> 0.15816462 | F33: ='2020'!F33*'Bobot M'!$J33 -> 188.16371 | G33: ='2020'!G33*'Bobot M'!$J33 -> 0.11377609 | H33: ='2020'!H33*'Bobot M'!$J33 -> 0.85667423 | I33: ='2020'!I33*'Bobot M'!$J33 -> 0.90264807 | J33: ='2020'!J33*'Bobot M'!$J33 -> 5733.3152 | ... N33: ='2020'!N33*'Bobot M'!$J33 -> 0.0044632423 | Q33: =-(Q18)/SQRT(Q18*Q18) -> -1 | R33: =-(R18)/SQRT(Q18*R19) -> 0.40546794 | S33: =-(S18)/SQRT(Q18*S20) -> -9.1261176e-05 | T33: =-(T18)/SQRT(Q18*T21) -> 0.41339424 | U33: =-(U18)/SQRT(Q18*U22) -> 0.77052692 | V33: =-(V18)/SQRT(Q18*V23) -> 0.34611345 | W33: =-(W18)/SQRT(Q18*W24) -> -0.30044807 | X33: =-(X18)/SQRT(Q18*X25) -> 0.43887088 | Y33: =-(Y18)/SQRT(Q18*Y26) -> 0.16134475 | Z33: =-(Z18)/SQRT(Q18*Z27) -> 0.24604612 | AA33: =-(AA18)/SQRT(Q18*AA28) -> 0.18394321 | AB33: =-(AB18)/SQRT(Q18*AB29) -> -0.27590373
A34: JAWA BARAT | B34: Kota Banjar | C34: ='2020'!C34*'Bobot M'!$J34 -> 0.24485391 | D34: ='2020'!D34*'Bobot M'!$J34 -> 0.29768362 | E34: ='2020'!E34*'Bobot M'!$J34 -> 0.020797215 | F34: ='2020'!F34*'Bobot M'!$J34 -> 11.104688 | G34: ='2020'!G34*'Bobot M'!$J34 -> 0.029471259 | H34: ='2020'!H34*'Bobot M'!$J34 -> 0.23577007 | I34: ='2020'!I34*'Bobot M'!$J34 -> 0.24891774 | J34: ='2020'!J34*'Bobot M'!$J34 -> 1175.992 | ... N34: ='2020'!N34*'Bobot M'!$J34 -> 0.0010654731 | Q34: =R33 -> 0.40546794 | R34: =-(R19)/SQRT(R19*R19) -> -1 | S34: =-(S19)/SQRT(R19*S20) -> -0.29546264 | T34: =-(T19)/SQRT(R19*T21) -> 0.042173236 | U34: =-(U19)/SQRT(R19*U22) -> -0.16488242 | V34: =-(V19)/SQRT(R19*V23) -> -0.06831509 | W34: =-(W19)/SQRT(R19*W24) -> 0.073479465 | X34: =-(X19)/SQRT(R19*X25) -> -0.16342539 | Y34: =-(Y19)/SQRT(R19*Y26) -> 0.20068798 | Z34: =-(Z19)/SQRT(R19*Z27) -> -0.070597364 | AA34: =-(AA19)/SQRT(R19*AA28) -> 0.26975998 | AB34: =-(AB19)/SQRT(R19*AB29) -> 0.22336445
A35: BANTEN | B35: Pandeglang | C35: ='2020'!C35*'Bobot M'!$J35 -> 0.0014053801 | D35: ='2020'!D35*'Bobot M'!$J35 -> 0.0018747771 | E35: ='2020'!E35*'Bobot M'!$J35 -> 0.00021448263 | F35: ='2020'!F35*'Bobot M'!$J35 -> 0.42186657 | G35: ='2020'!G35*'Bobot M'!$J35 -> 0.00015351075 | H35: ='2020'!H35*'Bobot M'!$J35 -> 0.0013554351 | I35: ='2020'!I35*'Bobot M'!$J35 -> 0.0014386768 | J35: ='2020'!J35*'Bobot M'!$J35 -> 7.820681 | ... N35: ='2020'!N35*'Bobot M'!$J35 -> 6.594476e-06 | Q35: =S33 -> -9.1261176e-05 | R35: =S34 -> -0.29546264 | S35: =-(S20)/SQRT(S20*S20) -> -1 | T35: =-(T20)/SQRT(S20*T21) -> -0.029086275 | U35: =-(U20)/SQRT(S20*U22) -> -0.17143521 | V35: =-(V20)/SQRT(S20*V23) -> -0.02993376 | W35: =-(W20)/SQRT(S20*W24) -> 0.043391559 | X35: =-(X20)/SQRT(S20*X25) -> 0.073122349 | Y35: =-(Y20)/SQRT(S20*Y26) -> 0.2882322 | Z35: =-(Z20)/SQRT(S20*Z27) -> 0.094506049 | AA35: =-(AA20)/SQRT(S20*AA28) -> 0.29813475 | AB35: =-(AB20)/SQRT(S20*AB29) -> 0.043468523
A36: BANTEN | B36: Lebak | C36: ='2020'!C36*'Bobot M'!$J36 -> 0.0015078412 | D36: ='2020'!D36*'Bobot M'!$J36 -> 0.001882973 | E36: ='2020'!E36*'Bobot M'!$J36 -> 0.00021800114 | F36: ='2020'!F36*'Bobot M'!$J36 -> 0.48653984 | G36: ='2020'!G36*'Bobot M'!$J36 -> 0.00015099646 | H36: ='2020'!H36*'Bobot M'!$J36 -> 0.0015380405 | I36: ='2020'!I36*'Bobot M'!$J36 -> 0.0016309977 | J36: ='2020'!J36*'Bobot M'!$J36 -> 7.8921366 | ... N36: ='2020'!N36*'Bobot M'!$J36 -> 7.4082637e-06 | Q36: =T33 -> 0.41339424 | R36: =T34 -> 0.042173236 | S36: =T35 -> -0.029086275 | T36: =-(T21)/SQRT(T21*T21) -> -1 | U36: =-(U21)/SQRT(T21*U22) -> -0.33804008 | V36: =-(V21)/SQRT(T21*V23) -> -0.32200213 | W36: =-(W21)/SQRT(T21*W24) -> 0.29186722 | X36: =-(X21)/SQRT(T21*X25) -> -0.047093733 | Y36: =-(Y21)/SQRT(T21*Y26) -> -0.28508707 | Z36: =-(Z21)/SQRT(T21*Z27) -> -0.026292248 | AA36: =-(AA21)/SQRT(T21*AA28) -> -0.16442098 | AB36: =-(AB21)/SQRT(T21*AB29) -> 0.36524273
A37: BANTEN | B37: Tangerang | C37: ='2020'!C37*'Bobot M'!$J37 -> 0.0039762162 | D37: ='2020'!D37*'Bobot M'!$J37 -> 0.0050299798 | E37: ='2020'!E37*'Bobot M'!$J37 -> 0.00034443585 | F37: ='2020'!F37*'Bobot M'!$J37 -> 5.168218 | G37: ='2020'!G37*'Bobot M'!$J37 -> 0.00046385503 | H37: ='2020'!H37*'Bobot M'!$J37 -> 0.0037517523 | I37: ='2020'!I37*'Bobot M'!$J37 -> 0.0039701346 | J37: ='2020'!J37*'Bobot M'!$J37 -> 28.790083 | ... N37: ='2020'!N37*'Bobot M'!$J37 -> 1.5756696e-05 | Q37: =U33 -> 0.77052692 | R37: =U34 -> -0.16488242 | S37: =U35 -> -0.17143521 | T37: =U36 -> -0.33804008 | U37: =-(U22)/SQRT(U22*U22) -> -1 | V37: =-(V22)/SQRT(U22*V23) -> -0.1317937 | W37: =-(W22)/SQRT(U22*W24) -> 0.10300317 | X37: =-(X22)/SQRT(U22*X25) -> -0.14329122 | Y37: =-(Y22)/SQRT(U22*Y26) -> -0.31266279 | Z37: =-(Z22)/SQRT(U22*Z27) -> -0.31925607 | AA37: =-(AA22)/SQRT(U22*AA28) -> -0.26966759 | AB37: =-(AB22)/SQRT(U22*AB29) -> 0.47906451
A38: BANTEN | B38: Serang | C38: ='2020'!C38*'Bobot M'!$J38 -> 0.0018445185 | D38: ='2020'!D38*'Bobot M'!$J38 -> 0.002548035 | E38: ='2020'!E38*'Bobot M'!$J38 -> 0.00013661052 | F38: ='2020'!F38*'Bobot M'!$J38 -> 1.4619656 | G38: ='2020'!G38*'Bobot M'!$J38 -> 0.00020740463 | H38: ='2020'!H38*'Bobot M'!$J38 -> 0.0017333496 | I38: ='2020'!I38*'Bobot M'!$J38 -> 0.0018389877 | J38: ='2020'!J38*'Bobot M'!$J38 -> 9.4320436 | ... N38: ='2020'!N38*'Bobot M'!$J38 -> 8.379147e-06 | Q38: =V33 -> 0.34611345 | R38: =V34 -> -0.06831509 | S38: =V35 -> -0.02993376 | T38: =V36 -> -0.32200213 | U38: =V37 -> -0.1317937 | V38: =-(V23)/SQRT(V23*V23) -> -1 | W38: =-(W23)/SQRT(V23*W24) -> 0.99742856 | X38: =-(X23)/SQRT(V23*X25) -> -0.26546983 | Y38: =-(Y23)/SQRT(V23*Y26) -> -0.29206022 | Z38: =-(Z23)/SQRT(V23*Z27) -> -0.40497754 | AA38: =-(AA23)/SQRT(V23*AA28) -> -0.36127822 | AB38: =-(AB23)/SQRT(V23*AB29) -> 0.085254824
A39: BANTEN | B39: Kota Tangerang | C39: ='2020'!C39*'Bobot M'!$J39 -> 0.0025146435 | D39: ='2020'!D39*'Bobot M'!$J39 -> 0.00305485 | E39: ='2020'!E39*'Bobot M'!$J39 -> 0.00016775002 | F39: ='2020'!F39*'Bobot M'!$J39 -> 3.2912329 | G39: ='2020'!G39*'Bobot M'!$J39 -> 0.00034353405 | H39: ='2020'!H39*'Bobot M'!$J39 -> 0.0022369883 | I39: ='2020'!I39*'Bobot M'!$J39 -> 0.0023616761 | J39: ='2020'!J39*'Bobot M'!$J39 -> 20.336798 | ... N39: ='2020'!N39*'Bobot M'!$J39 -> 1.0894111e-05 | Q39: =W33 -> -0.30044807 | R39: =W34 -> 0.073479465 | S39: =W35 -> 0.043391559 | T39: =W36 -> 0.29186722 | U39: =W37 -> 0.10300317 | V39: =W38 -> 0.99742856 | W39: =-(W24)/SQRT(W24*W24) -> -1 | X39: =-(X24)/SQRT(W24*X25) -> 0.24903465 | Y39: =-(Y24)/SQRT(W24*Y26) -> 0.29064556 | Z39: =-(Z24)/SQRT(W24*Z27) -> 0.41013222 | AA39: =-(AA24)/SQRT(W24*AA28) -> 0.37701487 | AB39: =-(AB24)/SQRT(W24*AB29) -> -0.067290445
A40: BANTEN | B40: Kota Cilegon | C40: ='2020'!C40*'Bobot M'!$J40 -> 0.00054115395 | D40: ='2020'!D40*'Bobot M'!$J40 -> 0.00064612523 | E40: ='2020'!E40*'Bobot M'!$J40 -> 2.7335497e-05 | F40: ='2020'!F40*'Bobot M'!$J40 -> 0.54314759 | G40: ='2020'!G40*'Bobot M'!$J40 -> 7.31169e-05 | H40: ='2020'!H40*'Bobot M'!$J40 -> 0.00047900088 | I40: ='2020'!I40*'Bobot M'!$J40 -> 0.00050804022 | J40: ='2020'!J40*'Bobot M'!$J40 -> 3.7378589 | ... N40: ='2020'!N40*'Bobot M'!$J40 -> 2.7631817e-06 | Q40: =X33 -> 0.43887088 | R40: =X34 -> -0.16342539 | S40: =X35 -> 0.073122349 | T40: =X36 -> -0.047093733 | U40: =X37 -> -0.14329122 | V40: =X38 -> -0.26546983 | W40: =X39 -> 0.24903465 | X40: =-(X25)/SQRT(X25*X25) -> -1 | Y40: =-(Y25)/SQRT(X25*Y26) -> -0.52520191 | Z40: =-(Z25)/SQRT(X25*Z27) -> -0.15703054 | AA40: =-(AA25)/SQRT(X25*AA28) -> 0.12038601 | AB40: =-(AB25)/SQRT(X25*AB29) -> -0.00026787465
...

Sheet Quartile
A1: 63.91
A2: 65
A3: 65.36
A4: 65.67
A5: 66.12
A6: 66.7
A7: 66.88
A8: 67.29
A9: 67.59
A10: 68.06
A11: 68.08
A12: 68.75
... A41: 84.72

Sheet 2021
A1: Provinsi | B1: Kabupaten/Kota | C1: IPM | D1: IPG | E1: PPM | F1: PDRB_ADHK | G1: RLS | H1: AHH_L | I1: AHH_P | J1: GK | K1: PKKP | L1: TPT | M1: TPAK | N1: GR | O1: JP
A2: DKI JAKARTA | B2: Kep. Seribu | C2: 72.1 | D2: 93.39 | E2: 15.06 | F2: 3648.88 | G2: 8.81 | H2: 66.84 | I2: 71.03 | J2: 670785 | K2: 2.41 | L2: 8.58 | M2: 65.45 | N2: 0.245 | O2: 27996
A3: DKI JAKARTA | B3: Kota Jakarta Selatan | C3: 84.9 | D3: 96.28 | E3: 3.56 | F3: 429278 | G3: 11.64 | H3: 72.33 | I3: 76.12 | J3: 792684 | K3: 1.63 | L3: 7.33 | M3: 61.44 | N3: 0.383 | O3: 2232442
A4: DKI JAKARTA | B4: Kota Jakarta Timur | C4: 82.97 | D4: 95.44 | E4: 4.28 | F4: 313816.5 | G4: 11.67 | H4: 72.7 | I4: 76.27 | J4: 594849 | K4: 2.24 | L4: 8.23 | M4: 60.85 | N4: 0.374 | O4: 3051866
A5: DKI JAKARTA | B5: Kota Jakarta Pusat | C5: 81.56 | D5: 96.11 | E5: 4.94 | F5: 460024.3 | G5: 11.39 | H5: 72.3 | I5: 76 | J5: 689379 | K5: 3.08 | L5: 7.75 | M5: 63.17 | N5: 0.397 | O5: 1057465
A6: DKI JAKARTA | B6: Kota Jakarta Barat | C6: 81.76 | D6: 95.37 | E6: 4.31 | F6: 327613.1 | G6: 10.78 | H6: 71.82 | I6: 75.49 | J6: 570330 | K6: 2 | L6: 9.06 | M6: 63.21 | N6: 0.366 | O6: 2446687
A7: DKI JAKARTA | B7: Kota Jakarta Utara | C7: 80.51 | D7: 93.6 | E7: 7.24 | F7: 330883.9 | G7: 10.81 | H7: 71.44 | I7: 75.22 | J7: 609310 | K7: 2.63 | L7: 9.84 | M7: 65.79 | N7: 0.515 | O7: 1788981
A8: JAWA BARAT | B8: Bogor | C8: 70.6 | D8: 89.4 | E8: 8.13 | F8: 159589.6 | G8: 8.31 | H8: 69.52 | I8: 73.25 | J8: 418483 | K8: 4.73 | L8: 12.22 | M8: 62.55 | N8: 0.396 | O8: 5484150
A9: JAWA BARAT | B9: Sukabumi | C9: 67.07 | D9: 87.44 | E9: 7.7 | F9: 47935.63 | G9: 7.1 | H9: 69.27 | I9: 73.13 | J9: 342094 | K9: 4.81 | L9: 9.51 | M9: 64.93 | N9: 0.343 | O9: 2747450
A10: JAWA BARAT | B10: Cianjur | C10: 65.56 | D10: 84.3 | E10: 11.18 | F10: 32897.53 | G10: 7.19 | H10: 68.45 | I10: 72.23 | J10: 387631 | K10: 6.2 | L10: 9.32 | M10: 67.98 | N10: 0.372 | O10: 2500640
A11: JAWA BARAT | B11: Bandung | C11: 72.73 | D11: 93.85 | E11: 7.15 | F11: 83949.37 | G11: 9.07 | H11: 71.94 | I11: 75.52 | J11: 378819 | K11: 5.53 | L11: 8.32 | M11: 65.12 | N11: 0.386 | O11: 3652400
A12: JAWA BARAT | B12: Garut | C12: 66.45 | D12: 82.13 | E12: 10.65 | F12: 39981.19 | G12: 7.53 | H12: 69.74 | I12: 73.48 | J12: 320050 | K12: 5 | L12: 8.68 | M12: 62.76 | N12: 0.322 | O12: 2613530
A13: JAWA BARAT | B13: Tasikmalaya | C13: 65.9 | D13: 86.36 | E13: 11.15 | F13: 25179.48 | G13: 7.48 | H13: 67.78 | I13: 71.59 | J13: 333909 | K13: 7.12 | L13: 6.16 | M13: 68.18 | N13: 0.378 | O13: 1876890
... A42: BANTEN | B42: Kota Tangerang Selatan | C42: 81.6 | D42: 93.8 | E42: 2.57 | F42: 62393.12 | G42: 11.82 | H42: 70.55 | I42: 74.31 | J42: 665610 | K42: 1.89 | L42: 8.6 | M42: 62.56 | N42: 0.37 | O42: 1365.39
C47: RV
C48: =CORREL(C$2:C$42,C$2:C$42) -> 1 | D48: =CORREL(C$2:C$42,D$2:D$42) -> 0.77077537 | E48: =CORREL(C$2:C$42,E$2:E$42) -> -0.72840015 | F48: =CORREL(C$2:C$42,F$2:F$42) -> 0.23073561 | G48: =CORREL(C$2:C$42,G$2:G$42) -> 0.96309614 | H48: =CORREL(C$2:C$42,H$2:H$42) -> 0.63490223 | I48: =CORREL(C$2:C$42,I$2:I$42) -> 0.64028547 | J48: =CORREL(C$2:C$42,J$2:J$42) -> 0.83983872 | K48: =CORREL(C$2:C$42,K$2:K$42) -> -0.66748536 | L48: =CORREL(C$2:C$42,L$2:L$42) -> 0.18334897 | M48: =CORREL(C$2:C$42,M$2:M$42) -> -0.37673139 | N48: =CORREL(C$2:C$42,N$2:N$42) -> 0.50861555
C49: =D48 -> 0.77077537 | D49: =CORREL(D$2:D$42,D$2:D$42) -> 1 | E49: =CORREL(D$2:D$42,E$2:E$42) -> -0.52306683 | F49: =CORREL(D$2:D$42,F$2:F$42) -> 0.20242403 | G49: =CORREL(D$2:D$42,G$2:G$42) -> 0.73249618 | H49: =CORREL(D$2:D$42,H$2:H$42) -> 0.37857773 | I49: =CORREL(D$2:D$42,I$2:I$42) -> 0.38487454 | J49: =CORREL(D$2:D$42,J$2:J$42) -> 0.64817726 | K49: =CORREL(D$2:D$42,K$2:K$42) -> -0.55986762 | L49: =CORREL(D$2:D$42,L$2:L$42) -> 0.063819861 | M49: =CORREL(D$2:D$42,M$2:M$42) -> -0.13820417 | N49: =CORREL(D$2:D$42,N$2:N$42) -> 0.31046403
C50: =E48 -> -0.72840015 | D50: =E49 -> -0.52306683 | E50: =CORREL(E$2:E$42,E$2:E$42) -> 1 | F50: =CORREL(E$2:E$42,F$2:F$42) -> -0.15342037 | G50: =CORREL(E$2:E$42,G$2:G$42) -> -0.73559311 | H50: =CORREL(E$2:E$42,H$2:H$42) -> -0.27594652 | I50: =CORREL(E$2:E$42,I$2:I$42) -> -0.27191797 | J50: =CORREL(E$2:E$42,J$2:J$42) -> -0.54571567 | K50: =CORREL(E$2:E$42,K$2:K$42) -> 0.6383024 | L50: =CORREL(E$2:E$42,L$2:L$42) -> -0.15151302 | M50: =CORREL(E$2:E$42,M$2:M$42) -> 0.37853954 | N50: =CORREL(E$2:E$42,N$2:N$42) -> -0.25490517
C51: =F48 -> 0.23073561 | D51: =F49 -> 0.20242403 | E51: =F50 -> -0.15342037 | F51: =CORREL(F$2:F$42,F$2:F$42) -> 1 | G51: =CORREL(F$2:F$42,G$2:G$42) -> 0.23524927 | H51: =CORREL(F$2:F$42,H$2:H$42) -> 0.17265027 | I51: =CORREL(F$2:F$42,I$2:I$42) -> 0.17300088 | J51: =CORREL(F$2:F$42,J$2:J$42) -> 0.27075688 | K51: =CORREL(F$2:F$42,K$2:K$42) -> -0.03363847 | L51: =CORREL(F$2:F$42,L$2:L$42) -> 0.12706022 | M51: =CORREL(F$2:F$42,M$2:M$42) -> -0.4385954 | N51: =CORREL(F$2:F$42,N$2:N$42) -> 0.29837911
C52: =G48 -> 0.96309614 | D52: =G49 -> 0.73249618 | E52: =G50 -> -0.73559311 | F52: =G51 -> 0.23524927 | G52: =CORREL(G$2:G$42,G$2:G$42) -> 1 | H52: =CORREL(G$2:G$42,H$2:H$42) -> 0.54604163 | I52: =CORREL(G$2:G$42,I$2:I$42) -> 0.55039369 | J52: =CORREL(G$2:G$42,J$2:J$42) -> 0.81556004 | K52: =CORREL(G$2:G$42,K$2:K$42) -> -0.63051759 | L52: =CORREL(G$2:G$42,L$2:L$42) -> 0.19876589 | M52: =CORREL(G$2:G$42,M$2:M$42) -> -0.45191835 | N52: =CORREL(G$2:G$42,N$2:N$42) -> 0.53132269
C53: =H48 -> 0.63490223 | D53: =H49 -> 0.37857773 | E53: =H50 -> -0.27594652 | F53: =H51 -> 0.17265027 | G53: =H52 -> 0.54604163 | H53: =CORREL(H$2:H$42,H$2:H$42) -> 1 | I53: =CORREL(H$2:H$42,I$2:I$42) -> 0.99912998 | J53: =CORREL(H$2:H$42,J$2:J$42) -> 0.39738409 | K53: =CORREL(H$2:H$42,K$2:K$42) -> -0.12388948 | L53: =CORREL(H$2:H$42,L$2:L$42) -> 0.20385768 | M53: =CORREL(H$2:H$42,M$2:M$42) -> -0.056413189 | N53: =CORREL(H$2:H$42,N$2:N$42) -> 0.58101347
C54: =I48 -> 0.64028547 | D54: =I49 -> 0.38487454 | E54: =I50 -> -0.27191797 | F54: =I51 -> 0.17300088 | G54: =I52 -> 0.55039369 | H54: =I53 -> 0.99912998 | I54: =CORREL(I$2:I$42,I$2:I$42) -> 1 | J54: =CORREL(I$2:I$42,J$2:J$42) -> 0.41118729 | K54: =CORREL(I$2:I$42,K$2:K$42) -> -0.13360222 | L54: =CORREL(I$2:I$42,L$2:L$42) -> 0.19575996 | M54: =CORREL(I$2:I$42,M$2:M$42) -> -0.057707324 | N54: =CORREL(I$2:I$42,N$2:N$42) -> 0.5764193
C55: =J48 -> 0.83983872 | D55: =J49 -> 0.64817726 | E55: =J50 -> -0.54571567 | F55: =J51 -> 0.27075688 | G55: =J52 -> 0.81556004 | H55: =J53 -> 0.39738409 | I55: =J54 -> 0.41118729 | J55: =CORREL(J$2:J$42,J$2:J$42) -> 1 | K55: =CORREL(J$2:J$42,K$2:K$42) -> -0.7360257 | L55: =CORREL(J$2:J$42,L$2:L$42) -> 0.097188974 | M55: =CORREL(J$2:J$42,M$2:M$42) -> -0.32345591 | N55: =CORREL(J$2:J$42,N$2:N$42) -> 0.26267676
C56: =K48 -> -0.66748536 | D56: =K49 -> -0.55986762 | E56: =K50 -> 0.6383024 | F56: =K51 -> -0.03363847 | G56: =K52 -> -0.63051759 | H56: =K53 -> -0.12388948 | I56: =K54 -> -0.13360222 | J56: =K55 -> -0.7360257 | K56: =CORREL(K$2:K$42,K$2:K$42) -> 1 | L56: =CORREL(K$2:K$42,L$2:L$42) -> -0.2052094 | M56: =CORREL(K$2:K$42,M$2:M$42) -> 0.29268759 | N56: =CORREL(K$2:K$42,N$2:N$42) -> 0.033277798
C57: =L48 -> 0.18334897 | D57: =L49 -> 0.063819861 | E57: =L50 -> -0.15151302 | F57: =L51 -> 0.12706022 | G57: =L52 -> 0.19876589 | H57: =L53 -> 0.20385768 | I57: =L54 -> 0.19575996 | J57: =L55 -> 0.097188974 | K57: =L56 -> -0.2052094 | L57: =CORREL(L$2:L$42,L$2:L$42) -> 1 | M57: =CORREL(L$2:L$42,M$2:M$42) -> -0.57995127 | N57: =CORREL(L$2:L$42,N$2:N$42) -> 0.32246109
C58: =M48 -> -0.37673139 | D58: =M49 -> -0.13820417 | E58: =M50 -> 0.37853954 | F58: =M51 -> -0.4385954 | G58: =M52 -> -0.45191835 | H58: =M53 -> -0.056413189 | I58: =M54 -> -0.057707324 | J58: =M55 -> -0.32345591 | K58: =M56 -> 0.29268759 | L58: =M57 -> -0.57995127 | M58: =CORREL(M$2:M$42,M$2:M$42) -> 1 | N58: =CORREL(M$2:M$42,N$2:N$42) -> -0.24943301
C59: =N48 -> 0.50861555 | D59: =N49 -> 0.31046403 | E59: =N50 -> -0.25490517 | F59: =N51 -> 0.29837911 | G59: =N52 -> 0.53132269 | H59: =N53 -> 0.58101347 | I59: =N54 -> 0.5764193 | J59: =N55 -> 0.26267676 | K59: =N56 -> 0.033277798 | L59: =N57 -> 0.32246109 | M59: =N58 -> -0.24943301 | N59: =CORREL(N$2:N$42,N$2:N$42) -> 1
C60: =SUMSQ(C48:N59) - 12 -> 28.59663
C63: V
C64: {=MINVERSE(C48:N59)} -> 40.143582 | D64: -5.9861257 | E64: 3.5982708 | F64: 1.7015578 | G64: -16.6278 | H64: -21.241607 | I64: 11.91501 | J64: -6.2590621 | K64: 4.7913842 | L64: 2.9824766 | M64: 3.3378532 | N64: -2.4858182
C65: -5.9861257 | D65: 3.7561964 | E65: -0.8070024 | F65: -0.99292261 | G65: -0.81674182 | H65: 9.6711478 | I65: -7.9192403 | J65: 1.5136875 | K65: -0.33574831 | L65: -0.99360285 | M65: -1.935399 | N65: 0.79992861
C66: 3.5982708 | D66: -0.8070024 | E66: 3.5881436 | F66: 0.41054433 | G66: 1.3504858 | H66: 12.709306 | I66: -13.63824 | J66: -1.8885631 | K66: -1.173373 | L66: -0.1423193 | M66: 0.15426525 | N66: -0.40842956
C67: 1.7015578 | D67: -0.99292261 | E67: 0.41054433 | F67: 1.9095928 | G67: 1.5087313 | H67: -8.0293493 | I67: 7.2706585 | J67: -1.5001644 | K67: -0.080345878 | L67: 0.83461829 | M67: 1.6548059 | N67: -0.80935234
C68: -16.6278 | D68: -0.81674182 | E68: 1.3504858 | F68: 1.5087313 | G68: 20.925235 | H68: -12.856033 | I68: 14.604211 | J68: -2.6144054 | K68: -1.2867452 | L68: 1.2027694 | M68: 2.9832949 | N68: -2.3760245
C69: -21.241607 | D69: 9.6711478 | E69: 12.709306 | F69: -8.0293493 | G69: -12.856033 | H69: 890.22296 | I69: -879.75623 | J69: 22.890736 | K69: -14.048119 | L69: -18.573452 | M69: -19.163419 | N69: 5.8082167
C70: 11.91501 | D70: -7.9192403 | E70: -13.63824 | F70: 7.2706585 | G70: 14.604211 | H70: -879.75623 | I70: 873.68477 | J70: -21.539975 | K70: 12.224297 | L70: 17.011339 | M70: 17.098863 | N70: -5.4347048
C71: -6.2590621 | D71: 1.5136875 | E71: -1.8885631 | F71: -1.5001644 | G71: -2.6144054 | H71: 22.890736 | I71: -21.539975 | J71: 6.9646092 | K71: 1.5392074 | L71: -0.54111092 | M71: -1.4584718 | N71: 1.115082
C72: 4.7913842 | D72: -0.33574831 | E72: -1.173373 | F72: -0.080345878 | G72: -1.2867452 | H72: -14.048119 | I72: 12.224297 | J72: 1.5392074 | K72: 5.0614486 | L72: 1.7896684 | M72: 1.1355957 | N72: -1.6749488
C73: 2.9824766 | D73: -0.99360285 | E73: -0.1423193 | F73: 0.83461829 | G73: 1.2027694 | H73: -18.573452 | I73: 17.011339 | J73: -0.54111092 | K73: 1.7896684 | L73: 2.9508443 | M73: 2.5520788 | N73: -1.3794419
