Workbook

Sheet 1. Data Original
A1: Data Tahun 2020
A2: Provinsi | B2: Kabupaten/Kota | C2: PPM | D2: RLS | E2: TPT | F2: IPM | G2: JP
A3: DKI JAKARTA | B3: Kota Jakarta Pusat | C3: 4.51 | D3: 11.38 | E3: 10.97 | F3: 81.39 | G3: 1056896 | H3: =(C3-'2. Statistika Deskriptif'!B4)^3 -> -39.477655 | I3: =(D3-'2. Statistika Deskriptif'!B5)^3 -> 4.8054199 | J3: =(E3-'2. Statistika Deskriptif'!B6)^3 -> -1.25e-07 | K3: =(C3-'2. Statistika Deskriptif'!B4)^4 -> 134.42142 | L3: =(D3-'2. Statistika Deskriptif'!B5)^4 -> 8.1091461 | M3: =(E3-'2. Statistika Deskriptif'!B6)^4 -> 6.25e-10
A4: JAWA BARAT | B4: Bandung Barat | C4: 10.49 | D4: 8.19 | E4: 12.25 | F4: 68.08 | G4: 1782190 | H4: =(C4-'2. Statistika Deskriptif'!B4)^3 -> 17.073859 | I4: =(D4-'2. Statistika Deskriptif'!B5)^3 -> -3.3919031 | J4: =(E4-'2. Statistika Deskriptif'!B6)^3 -> 2.0726719 | K4: =(C4-'2. Statistika Deskriptif'!B4)^4 -> 43.965188 | L4: =(D4-'2. Statistika Deskriptif'!B5)^4 -> 5.0963345 | M4: =(E4-'2. Statistika Deskriptif'!B6)^4 -> 2.6426566
A5: JAWA BARAT | B5: Kota Tasikmalaya | C5: 12.97 | D5: 9.33 | E5: 7.99 | F5: 72.97 | G5: 713670 | H5: =(C5-'2. Statistika Deskriptif'!B4)^3 -> 129.17054 | I5: =(D5-'2. Statistika Deskriptif'!B5)^3 -> -0.047634766 | J5: =(E5-'2. Statistika Deskriptif'!B6)^3 -> -26.597022 | K5: =(C5-'2. Statistika Deskriptif'!B4)^4 -> 652.95709 | L5: =(D5-'2. Statistika Deskriptif'!B5)^4 -> 0.017267603 | M5: =(E5-'2. Statistika Deskriptif'!B6)^4 -> 79.39211
A6: BANTEN | B6: Kota Cilegon | C6: 3.69 | D6: 9.87 | E6: 12.69 | F6: 73.05 | G6: 433.76 | H6: =(C6-'2. Statistika Deskriptif'!B4)^3 -> -75.418891 | I6: =(D6-'2. Statistika Deskriptif'!B5)^3 -> 0.0055923594 | J6: =(E6-'2. Statistika Deskriptif'!B6)^3 -> 5.0442009 | K6: =(C6-'2. Statistika Deskriptif'!B4)^4 -> 318.64481 | L6: =(D6-'2. Statistika Deskriptif'!B5)^4 -> 0.00099264379 | M6: =(E6-'2. Statistika Deskriptif'!B6)^4 -> 8.6508045
A7: Data Tahun 2021
A8: Provinsi | B8: Kabupaten/Kota | C8: PPM | D8: RLS | E8: TPT | F8: IPM | G8: JP
A9: DKI JAKARTA | B9: Kota Jakarta Pusat | C9: 4.94 | D9: 11.39 | E9: 7.75 | F9: 81.79 | G9: 1057465 | H9: =(C9-'2. Statistika Deskriptif'!B9)^3 -> -41.511588 | I9: =(D9-'2. Statistika Deskriptif'!B10)^3 -> 4.0386696 | J9: =(E9-'2. Statistika Deskriptif'!B11)^3 -> -3.7058853 | K9: =(C9-'2. Statistika Deskriptif'!B9)^4 -> 143.73387 | L9: =(D9-'2. Statistika Deskriptif'!B10)^4 -> 6.4315813 | M9: =(E9-'2. Statistika Deskriptif'!B11)^4 -> 5.7348575
A10: JAWA BARAT | B10: Bandung Barat | C10: 11.3 | D10: 8.2 | E10: 11.65 | F10: 68.3 | G10: 1808420 | H10: =(C10-'2. Statistika Deskriptif'!B9)^3 -> 24.325979 | I10: =(D10-'2. Statistika Deskriptif'!B10)^3 -> -4.07683 | J10: =(E10-'2. Statistika Deskriptif'!B11)^3 -> 13.019338 | K10: =(C10-'2. Statistika Deskriptif'!B9)^4 -> 70.484525 | L10: =(D10-'2. Statistika Deskriptif'!B10)^4 -> 6.5127359 | M10: =(E10-'2. Statistika Deskriptif'!B11)^4 -> 30.627992
A11: JAWA BARAT | B11: Kota Tasikmalaya | C11: 13.13 | D11: 9.52 | E11: 7.66 | F11: 73.2 | G11: 723100 | H11: =(C11-'2. Statistika Deskriptif'!B9)^3 -> 105.65611 | I11: =(D11-'2. Statistika Deskriptif'!B10)^3 -> -0.021369234 | J11: =(E11-'2. Statistika Deskriptif'!B11)^3 -> -4.3908027 | K11: =(C11-'2. Statistika Deskriptif'!B9)^4 -> 499.48925 | L11: =(D11-'2. Statistika Deskriptif'!B10)^4 -> 0.0059299625 | M11: =(E11-'2. Statistika Deskriptif'!B11)^4 -> 7.1899395
A12: BANTEN | B12: Kota Cilegon | C12: 4.24 | D12: 10.08 | E12: 10.13 | F12: 73.3 | G12: 439.48 | H12: =(C12-'2. Statistika Deskriptif'!B9)^3 -> -72.121166 | I12: =(D12-'2. Statistika Deskriptif'!B10)^3 -> 0.022545266 | J12: =(E12-'2. Statistika Deskriptif'!B11)^3 -> 0.57696933 | K12: =(C12-'2. Statistika Deskriptif'!B9)^4 -> 300.20435 | L12: =(D12-'2. Statistika Deskriptif'!B10)^4 -> 0.0063690375 | M12: =(E12-'2. Statistika Deskriptif'!B11)^4 -> 0.48032697
A13: Data Tahun 2022
A14: Provinsi | B14: Kabupaten/Kota | C14: PPM | D14: RLS | E14: TPT | F14: IPM | G14: JP
A15: DKI JAKARTA | B15: Kota Jakarta Pusat | C15: 4.9 | D15: 11.53 | E15: 5.88 | F15: 82.13 | G15: 1053482 | H15: =(C15-'2. Statistika Deskriptif'!B14)^3 -> -30.371328 | I15: =(D15-'2. Statistika Deskriptif'!B15)^3 -> 4.2910156 | J15: =(E15-'2. Statistika Deskriptif'!B16)^3 -> -4.7204955 | K15: =(C15-'2. Statistika Deskriptif'!B14)^4 -> 94.758543 | L15: =(D15-'2. Statistika Deskriptif'!B15)^4 -> 6.9729004 | M15: =(E15-'2. Statistika Deskriptif'!B16)^4 -> 7.9186312
A16: JAWA BARAT | B16: Bandung Barat | C16: 10.82 | D16: 8.22 | E16: 9.63 | F16: 69.04 | G16: 1834230 | H16: =(C16-'2. Statistika Deskriptif'!B14)^3 -> 21.952 | I16: =(D16-'2. Statistika Deskriptif'!B15)^3 -> -4.7840941 | J16: =(E16-'2. Statistika Deskriptif'!B16)^3 -> 8.9019186 | K16: =(C16-'2. Statistika Deskriptif'!B14)^4 -> 61.4656 | L16: =(D16-'2. Statistika Deskriptif'!B15)^4 -> 8.0611986 | M16: =(E16-'2. Statistika Deskriptif'!B16)^4 -> 18.449226
A17: JAWA BARAT | B17: Kota Tasikmalaya | C17: 12.72 | D17: 9.53 | E17: 6.62 | F17: 73.83 | G17: 732480 | H17: =(C17-'2. Statistika Deskriptif'!B14)^3 -> 103.823 | I17: =(D17-'2. Statistika Deskriptif'!B15)^3 -> -0.052734375 | J17: =(E17-'2. Statistika Deskriptif'!B16)^3 -> -0.82397461 | K17: =(C17-'2. Statistika Deskriptif'!B14)^4 -> 487.9681 | L17: =(D17-'2. Statistika Deskriptif'!B15)^4 -> 0.019775391 | M17: =(E17-'2. Statistika Deskriptif'!B16)^4 -> 0.7724762
A18: BANTEN | B18: Kota Cilegon | C18: 3.64 | D18: 10.34 | E18: 8.1 | F18: 73.95 | G18: 445.06 | H18: =(C18-'2. Statistika Deskriptif'!B14)^3 -> -84.027672 | I18: =(D18-'2. Statistika Deskriptif'!B15)^3 -> 0.082312875 | J18: =(E18-'2. Statistika Deskriptif'!B16)^3 -> 0.15966114 | K18: =(C18-'2. Statistika Deskriptif'!B14)^4 -> 368.0412 | L18: =(D18-'2. Statistika Deskriptif'!B15)^4 -> 0.035806101 | M18: =(E18-'2. Statistika Deskriptif'!B16)^4 -> 0.086616169
A20: Provinsi | B20: Kabupaten/Kota | C20: Rata-rata | D20: Bobot | E20: Bobot^(1/2)
A21: DKI JAKARTA | B21: Kota Jakarta Pusat | C21: =(G3+G9+G15)/3 -> 1055947.7 | D21: =C21/C$25 -> 0.29432027 | E21: =SQRT(D21) -> 0.54251292
A22: JAWA BARAT | B22: Bandung Barat | C22: =(G4+G10+G16)/3 -> 1808280 | D22: =C22/C$25 -> 0.50401499 | E22: =SQRT(D22) -> 0.70994013
A23: JAWA BARAT | B23: Kota Tasikmalaya | C23: =(G5+G11+G17)/3 -> 723083.33 | D23: =C23/C$25 -> 0.20154226 | E23: =SQRT(D23) -> 0.44893458
A24: BANTEN | B24: Kota Cilegon | C24: =(G6+G12+G18)/3 -> 439.43333 | D24: =C24/C$25 -> 0.00012248158 | E24: =SQRT(D24) -> 0.01106714
C25: =SUM(C21:C24) -> 3587750.4
A27: Data Tahun 2020
A28: Provinsi | B28: Kabupaten/Kota | C28: PPM | D28: RLS | E28: TPT | F28: IPM | G28: JP
A29: DKI JAKARTA | B29: Kota Jakarta Pusat | C29: =C3*$D21 -> 1.3273844 | D29: =D3*$D21 -> 3.3493646 | E29: =E3*$D21 -> 3.2286933 | F29: =F3*$D21 -> 23.954727 | G29: =G3*$D21 -> 311065.91 | H29: =((C3-'2. Statistika Deskriptif'!B$21)^2)*$D21 -> 6.5540864 | I29: =((D3-'2. Statistika Deskriptif'!B$22)^2)*$D21 -> 1.2023175 | J29: =((E3-'2. Statistika Deskriptif'!B$23)^2)*$D21 -> 0.00058949797 | K29: =((C3-'2. Statistika Deskriptif'!B$21)^3)*$D21 -> -30.92845 | L29: =((D3-'2. Statistika Deskriptif'!B$22)^3)*$D21 -> 2.4300692 | M29: =((E3-'2. Statistika Deskriptif'!B$23)^3)*$D21 -> -2.6382344e-05 | N29: =((C3-'2. Statistika Deskriptif'!B$21)^4)*$D21 -> 145.95002 | O29: =((D3-'2. Statistika Deskriptif'!B$22)^4)*$D21 -> 4.9115451 | P29: =((E3-'2. Statistika Deskriptif'!B$23)^4)*$D21 -> 1.1807133e-06
A30: JAWA BARAT | B30: Bandung Barat | C30: =C4*$D22 -> 5.2871172 | D30: =D4*$D22 -> 4.1278828 | E30: =E4*$D22 -> 6.1741836 | F30: =F4*$D22 -> 34.313341 | G30: =G4*$D22 -> 898250.48 | H30: =((C4-'2. Statistika Deskriptif'!B$21)^2)*$D22 -> 0.80149982 | I30: =((D4-'2. Statistika Deskriptif'!B$22)^2)*$D22 -> 0.6885853 | J30: =((E4-'2. Statistika Deskriptif'!B$23)^2)*$D22 -> 0.76904264 | K30: =((C4-'2. Statistika Deskriptif'!B$21)^3)*$D22 -> 1.0107259 | L30: =((D4-'2. Statistika Deskriptif'!B$22)^3)*$D22 -> -0.80484989 | M30: =((E4-'2. Statistika Deskriptif'!B$23)^3)*$D22 -> 0.94995691 | N30: =((C4-'2. Statistika Deskriptif'!B$21)^4)*$D22 -> 1.2745692 | O30: =((D4-'2. Statistika Deskriptif'!B$22)^4)*$D22 -> 0.94074526 | P30: =((E4-'2. Statistika Deskriptif'!B$23)^4)*$D22 -> 1.1734306
A31: JAWA BARAT | B31: Kota Tasikmalaya | C31: =C5*$D23 -> 2.6140031 | D31: =D5*$D23 -> 1.8803893 | E31: =E5*$D23 -> 1.6103227 | F31: =F5*$D23 -> 14.706539 | G31: =G5*$D23 -> 143834.67 | H31: =((C5-'2. Statistika Deskriptif'!B$21)^2)*$D23 -> 2.8206655 | I31: =((D5-'2. Statistika Deskriptif'!B$22)^2)*$D23 -> 0.00016769698 | J31: =((E5-'2. Statistika Deskriptif'!B$23)^2)*$D23 -> 1.8439376 | K31: =((C5-'2. Statistika Deskriptif'!B$21)^3)*$D23 -> 10.552232 | L31: =((D5-'2. Statistika Deskriptif'!B$22)^3)*$D23 -> -4.83732e-06 | M31: =((E5-'2. Statistika Deskriptif'!B$23)^3)*$D23 -> -5.5774575 | N31: =((C5-'2. Statistika Deskriptif'!B$21)^4)*$D23 -> 39.476355 | O31: =((D5-'2. Statistika Deskriptif'!B$22)^4)*$D23 -> 1.3953539e-07 | P31: =((E5-'2. Statistika Deskriptif'!B$23)^4)*$D23 -> 16.870436
A32: BANTEN | B32: Kota Cilegon | C32: =C6*$D24 -> 0.00045195702 | D32: =D6*$D24 -> 0.0012088932 | E32: =E6*$D24 -> 0.0015542912 | F32: =F6*$D24 -> 0.0089472792 | G32: =G6*$D24 -> 0.053127609 | H32: =((C6-'2. Statistika Deskriptif'!B$21)^2)*$D24 -> 0.0037577399 | I32: =((D6-'2. Statistika Deskriptif'!B$22)^2)*$D24 -> 3.2001842e-05 | J32: =((E6-'2. Statistika Deskriptif'!B$23)^2)*$D24 -> 0.00034373835 | K32: =((C6-'2. Statistika Deskriptif'!B$21)^3)*$D24 -> -0.020813959 | L32: =((D6-'2. Statistika Deskriptif'!B$22)^3)*$D24 -> 1.6357883e-05 | M32: =((E6-'2. Statistika Deskriptif'!B$23)^3)*$D24 -> 0.00057584633 | N32: =((C6-'2. Statistika Deskriptif'!B$21)^4)*$D24 -> 0.11528762 | O32: =((D6-'2. Statistika Deskriptif'!B$22)^4)*$D24 -> 8.3614036e-06 | P32: =((E6-'2. Statistika Deskriptif'!B$23)^4)*$D24 -> 0.00096468431
A33: Data Tahun 2021
A34: Provinsi | B34: Kabupaten/Kota | C34: PPM | D34: RLS | E34: TPT | F34: IPM | G34: JP
A35: DKI JAKARTA | B35: Kota Jakarta Pusat | C35: =C9*$D21 -> 1.4539421 | D35: =D9*$D21 -> 3.3523078 | E35: =E9*$D21 -> 2.2809821 | F35: =F9*$D21 -> 24.072455 | G35: =G9*$D21 -> 311233.38 | H35: =((C9-'2. Statistika Deskriptif'!B$26)^2)*$D21 -> 6.9405192 | I35: =((D9-'2. Statistika Deskriptif'!B$27)^2)*$D21 -> 1.1595155 | J35: =((E9-'2. Statistika Deskriptif'!B$28)^2)*$D21 -> 1.1166418 | K35: =((C9-'2. Statistika Deskriptif'!B$26)^3)*$D21 -> -33.703722 | L35: =((D9-'2. Statistika Deskriptif'!B$27)^3)*$D21 -> 2.301467 | M35: =((E9-'2. Statistika Deskriptif'!B$28)^3)*$D21 -> -2.1750073 | N35: =((C9-'2. Statistika Deskriptif'!B$26)^4)*$D21 -> 163.66799 | O35: =((D9-'2. Statistika Deskriptif'!B$27)^4)*$D21 -> 4.5680721 | P35: =((E9-'2. Statistika Deskriptif'!B$28)^4)*$D21 -> 4.2365035
A36: JAWA BARAT | B36: Bandung Barat | C36: =C10*$D22 -> 5.6953694 | D36: =D10*$D22 -> 4.1329229 | E36: =E10*$D22 -> 5.8717746 | F36: =F10*$D22 -> 34.424224 | G36: =G10*$D22 -> 911470.79 | H36: =((C10-'2. Statistika Deskriptif'!B$26)^2)*$D22 -> 1.1399676 | I36: =((D10-'2. Statistika Deskriptif'!B$27)^2)*$D22 -> 0.73202179 | J36: =((E10-'2. Statistika Deskriptif'!B$28)^2)*$D22 -> 1.9208219 | K36: =((C10-'2. Statistika Deskriptif'!B$26)^3)*$D22 -> 1.7144193 | L36: =((D10-'2. Statistika Deskriptif'!B$27)^3)*$D22 -> -0.88219438 | M36: =((E10-'2. Statistika Deskriptif'!B$28)^3)*$D22 -> 3.7498071 | N36: =((C10-'2. Statistika Deskriptif'!B$26)^4)*$D22 -> 2.5783482 | O36: =((D10-'2. Statistika Deskriptif'!B$27)^4)*$D22 -> 1.0631745 | P36: =((E10-'2. Statistika Deskriptif'!B$28)^4)*$D22 -> 7.3203316
A37: JAWA BARAT | B37: Kota Tasikmalaya | C37: =C11*$D23 -> 2.6462499 | D37: =D11*$D23 -> 1.9186823 | E37: =E11*$D23 -> 1.5438137 | F37: =F11*$D23 -> 14.752893 | G37: =G11*$D23 -> 145735.21 | H37: =((C11-'2. Statistika Deskriptif'!B$26)^2)*$D23 -> 2.2401458 | I37: =((D11-'2. Statistika Deskriptif'!B$27)^2)*$D23 -> 0.0026585541 | J37: =((E11-'2. Statistika Deskriptif'!B$28)^2)*$D23 -> 0.83693938 | K37: =((C11-'2. Statistika Deskriptif'!B$26)^3)*$D23 -> 7.4684653 | L37: =((D11-'2. Statistika Deskriptif'!B$27)^3)*$D23 -> 0.00030534105 | M37: =((E11-'2. Statistika Deskriptif'!B$28)^3)*$D23 -> -1.7055244 | N37: =((C11-'2. Statistika Deskriptif'!B$26)^4)*$D23 -> 24.899261 | O37: =((D11-'2. Statistika Deskriptif'!B$27)^4)*$D23 -> 3.5069121e-05 | P37: =((E11-'2. Statistika Deskriptif'!B$28)^4)*$D23 -> 3.4755367
A38: BANTEN | B38: Kota Cilegon | C38: =C12*$D24 -> 0.00051932189 | D38: =D12*$D24 -> 0.0012346143 | E38: =E12*$D24 -> 0.0012407384 | F38: =F12*$D24 -> 0.0089778996 | G38: =G12*$D24 -> 0.053828204 | H38: =((C12-'2. Statistika Deskriptif'!B$26)^2)*$D24 -> 0.0037810103 | I38: =((D12-'2. Statistika Deskriptif'!B$27)^2)*$D24 -> 5.5781249e-05 | J38: =((E12-'2. Statistika Deskriptif'!B$28)^2)*$D24 -> 2.287799e-05 | K38: =((C12-'2. Statistika Deskriptif'!B$26)^3)*$D24 -> -0.021007599 | L38: =((D12-'2. Statistika Deskriptif'!B$27)^3)*$D24 -> 3.7644104e-05 | M38: =((E12-'2. Statistika Deskriptif'!B$28)^3)*$D24 -> 9.8876117e-06 | N38: =((C12-'2. Statistika Deskriptif'!B$26)^4)*$D24 -> 0.11671991 | O38: =((D12-'2. Statistika Deskriptif'!B$27)^4)*$D24 -> 2.540421e-05 | P38: =((E12-'2. Statistika Deskriptif'!B$28)^4)*$D24 -> 4.2733154e-06
A39: Data Tahun 2022
A40: Provinsi | B40: Kabupaten/Kota | C40: PPM | D40: RLS | E40: TPT | F40: IPM | G40: JP
A41: DKI JAKARTA | B41: Kota Jakarta Pusat | C41: =C15*$D21 -> 1.4421693 | D41: =D15*$D21 -> 3.3935127 | E41: =E15*$D21 -> 1.7306032 | F41: =F15*$D21 -> 24.172524 | G41: =G15*$D21 -> 310061.1 | H41: =((C15-'2. Statistika Deskriptif'!B$31)^2)*$D21 -> 6.1191053 | I41: =((D15-'2. Statistika Deskriptif'!B$32)^2)*$D21 -> 1.2629856 | J41: =((E15-'2. Statistika Deskriptif'!B$33)^2)*$D21 -> 1.2242061 | K41: =((C15-'2. Statistika Deskriptif'!B$31)^3)*$D21 -> -27.901131 | L41: =((D15-'2. Statistika Deskriptif'!B$32)^3)*$D21 -> 2.6162997 | M41: =((E15-'2. Statistika Deskriptif'!B$33)^3)*$D21 -> -2.496731 | N41: =((C15-'2. Statistika Deskriptif'!B$31)^4)*$D21 -> 127.22009 | O41: =((D15-'2. Statistika Deskriptif'!B$32)^4)*$D21 -> 5.4197169 | P41: =((E15-'2. Statistika Deskriptif'!B$33)^4)*$D21 -> 5.0920064
A42: JAWA BARAT | B42: Bandung Barat | C42: =C16*$D22 -> 5.4534422 | D42: =D16*$D22 -> 4.1430032 | E42: =E16*$D22 -> 4.8536644 | F42: =F16*$D22 -> 34.797195 | G42: =G16*$D22 -> 924479.42 | H42: =((C16-'2. Statistika Deskriptif'!B$31)^2)*$D22 -> 0.93267187 | I42: =((D16-'2. Statistika Deskriptif'!B$32)^2)*$D22 -> 0.77307481 | J42: =((E16-'2. Statistika Deskriptif'!B$33)^2)*$D22 -> 1.474705 | K42: =((C16-'2. Statistika Deskriptif'!B$31)^3)*$D22 -> 1.268737 | L42: =((D16-'2. Statistika Deskriptif'!B$32)^3)*$D22 -> -0.95743778 | M42: =((E16-'2. Statistika Deskriptif'!B$33)^3)*$D22 -> 2.522528 | N42: =((C16-'2. Statistika Deskriptif'!B$31)^4)*$D22 -> 1.7258947 | O42: =((D16-'2. Statistika Deskriptif'!B$32)^4)*$D22 -> 1.1857676 | P42: =((E16-'2. Statistika Deskriptif'!B$33)^4)*$D22 -> 4.3148614
...

Sheet 2. Statistika Deskriptif
A1: TANPA BOBOT
A2: Data Tahun 2020
A3: Indikator | B3: Rata-rata | C3: Simpangan Baku | D3: Min | E3: Q1 | F3: Q2 | G3: Q3 | H3: Max | I3: Skewness | J3: Kurtosis | K3: CV (%)
A4: PPM | B4: =AVERAGE('1. Data Original'!C3:C6) -> 7.915 | C4: =_xlfn.STDEV.P('1. Data Original'!C3:C6) -> 3.9251847 | D4: =MIN('1. Data Original'!C3:C6) -> 3.69 | E4: =_xlfn.QUARTILE.INC('1. Data Original'!C3:C6,1) -> 4.305 | F4: =_xlfn.QUARTILE.INC('1. Data Original'!C3:C6,2) -> 7.5 | G4: =_xlfn.QUARTILE.INC('1. Data Original'!C3:C6,3) -> 11.11 | H4: =MAX('1. Data Original'!C3:C6) -> 12.97 | I4: =((1/4)*SUM('1. Data Original'!H3:H6))/(C4^3) -> 0.12958882 | J4: =((1/4)*SUM('1. Data Original'!K3:K6))/(C4^4)-3 -> -1.7888634 | K4: =C4/B4*100 -> 49.591721
A5: RLS | B5: =AVERAGE('1. Data Original'!D3:D6) -> 9.6925 | C5: =_xlfn.STDEV.P('1. Data Original'!D3:D6) -> 1.1476144 | D5: =MIN('1. Data Original'!D3:D6) -> 8.19 | E5: =_xlfn.QUARTILE.INC('1. Data Original'!D3:D6,1) -> 9.045 | F5: =_xlfn.QUARTILE.INC('1. Data Original'!D3:D6,2) -> 9.6 | G5: =_xlfn.QUARTILE.INC('1. Data Original'!D3:D6,3) -> 10.2475 | H5: =MAX('1. Data Original'!D3:D6) -> 11.38 | I5: =((1/4)*SUM('1. Data Original'!I3:I6))/(C5^3) -> 0.22685051 | J5: =((1/4)*SUM('1. Data Original'!L3:L6))/(C5^4)-3 -> -1.0940547 | K5: =C5/B5*100 -> 11.840231
A6: TPT | B6: =AVERAGE('1. Data Original'!E3:E6) -> 10.975 | C6: =_xlfn.STDEV.P('1. Data Original'!E3:E6) -> 1.8355585 | D6: =MIN('1. Data Original'!E3:E6) -> 7.99 | E6: =_xlfn.QUARTILE.INC('1. Data Original'!E3:E6,1) -> 10.225 | F6: =_xlfn.QUARTILE.INC('1. Data Original'!E3:E6,2) -> 11.61 | G6: =_xlfn.QUARTILE.INC('1. Data Original'!E3:E6,3) -> 12.36 | H6: =MAX('1. Data Original'!E3:E6) -> 12.69 | I6: =((1/4)*SUM('1. Data Original'!J3:J6))/(C6^3) -> -0.78745835 | J6: =((1/4)*SUM('1. Data Original'!M3:M6))/(C6^4)-3 -> -1.0028749 | K6: =C6/B6*100 -> 16.724907
A7: Data Tahun 2021
A8: Indikator | B8: Rata-rata | C8: Simpangan Baku | D8: Min | E8: Q1 | F8: Q2 | G8: Q3 | H8: Max | I8: Skewness | J8: Kurtosis | K8: CV (%)
A9: PPM | B9: =AVERAGE('1. Data Original'!C9:C12) -> 8.4025 | C9: =_xlfn.STDEV.P('1. Data Original'!C9:C12) -> 3.8749218 | D9: =MIN('1. Data Original'!C9:C12) -> 4.24 | E9: =_xlfn.QUARTILE.INC('1. Data Original'!C9:C12,1) -> 4.765 | F9: =_xlfn.QUARTILE.INC('1. Data Original'!C9:C12,2) -> 8.12 | G9: =_xlfn.QUARTILE.INC('1. Data Original'!C9:C12,3) -> 11.7575 | H9: =MAX('1. Data Original'!C9:C12) -> 13.13 | I9: =((1/4)*SUM('1. Data Original'!H9:H12))/(C9^3) -> 0.070250799 | J9: =((1/4)*SUM('1. Data Original'!K9:K12))/(C9^4)-3 -> -1.8756837 | K9: =C9/B9*100 -> 46.116296
A10: RLS | B10: =AVERAGE('1. Data Original'!D9:D12) -> 9.7975 | C10: =_xlfn.STDEV.P('1. Data Original'!D9:D12) -> 1.1450846 | D10: =MIN('1. Data Original'!D9:D12) -> 8.2 | E10: =_xlfn.QUARTILE.INC('1. Data Original'!D9:D12,1) -> 9.19 | F10: =_xlfn.QUARTILE.INC('1. Data Original'!D9:D12,2) -> 9.8 | G10: =_xlfn.QUARTILE.INC('1. Data Original'!D9:D12,3) -> 10.4075 | H10: =MAX('1. Data Original'!D9:D12) -> 11.39 | I10: =((1/4)*SUM('1. Data Original'!I9:I12))/(C10^3) -> -0.0061580834 | J10: =((1/4)*SUM('1. Data Original'!L9:L12))/(C10^4)-3 -> -1.1159983 | K10: =C10/B10*100 -> 11.687518
A11: TPT | B11: =AVERAGE('1. Data Original'!E9:E12) -> 9.2975 | C11: =_xlfn.STDEV.P('1. Data Original'!E9:E12) -> 1.681032 | D11: =MIN('1. Data Original'!E9:E12) -> 7.66 | E11: =_xlfn.QUARTILE.INC('1. Data Original'!E9:E12,1) -> 7.7275 | F11: =_xlfn.QUARTILE.INC('1. Data Original'!E9:E12,2) -> 8.94 | G11: =_xlfn.QUARTILE.INC('1. Data Original'!E9:E12,3) -> 10.51 | H11: =MAX('1. Data Original'!E9:E12) -> 11.65 | I11: =((1/4)*SUM('1. Data Original'!J9:J12))/(C11^3) -> 0.28943073 | J11: =((1/4)*SUM('1. Data Original'!M9:M12))/(C11^4)-3 -> -1.6214724 | K11: =C11/B11*100 -> 18.080474
A12: Data Tahun 2022
A13: Indikator | B13: Rata-rata | C13: Simpangan Baku | D13: Min | E13: Q1 | F13: Q2 | G13: Q3 | H13: Max | I13: Skewness | J13: Kurtosis | K13: CV (%)
A14: PPM | B14: =AVERAGE('1. Data Original'!C15:C18) -> 8.02 | C14: =_xlfn.STDEV.P('1. Data Original'!C15:C18) -> 3.8356486 | D14: =MIN('1. Data Original'!C15:C18) -> 3.64 | E14: =_xlfn.QUARTILE.INC('1. Data Original'!C15:C18,1) -> 4.585 | F14: =_xlfn.QUARTILE.INC('1. Data Original'!C15:C18,2) -> 7.86 | G14: =_xlfn.QUARTILE.INC('1. Data Original'!C15:C18,3) -> 11.295 | H14: =MAX('1. Data Original'!C15:C18) -> 12.72 | I14: =((1/4)*SUM('1. Data Original'!H15:H18))/(C14^3) -> 0.050397984 | J14: =((1/4)*SUM('1. Data Original'!K15:K18))/(C14^4)-3 -> -1.8308629 | K14: =C14/B14*100 -> 47.826042
A15: RLS | B15: =AVERAGE('1. Data Original'!D15:D18) -> 9.905 | C15: =_xlfn.STDEV.P('1. Data Original'!D15:D18) -> 1.205166 | D15: =MIN('1. Data Original'!D15:D18) -> 8.22 | E15: =_xlfn.QUARTILE.INC('1. Data Original'!D15:D18,1) -> 9.2025 | F15: =_xlfn.QUARTILE.INC('1. Data Original'!D15:D18,2) -> 9.935 | G15: =_xlfn.QUARTILE.INC('1. Data Original'!D15:D18,3) -> 10.6375 | H15: =MAX('1. Data Original'!D15:D18) -> 11.53 | I15: =((1/4)*SUM('1. Data Original'!I15:I18))/(C15^3) -> -0.066198656 | J15: =((1/4)*SUM('1. Data Original'!L15:L18))/(C15^4)-3 -> -1.2117319 | K15: =C15/B15*100 -> 12.167248
A16: TPT | B16: =AVERAGE('1. Data Original'!E15:E18) -> 7.5575 | C16: =_xlfn.STDEV.P('1. Data Original'!E15:E18) -> 1.4389645 | D16: =MIN('1. Data Original'!E15:E18) -> 5.88 | E16: =_xlfn.QUARTILE.INC('1. Data Original'!E15:E18,1) -> 6.435 | F16: =_xlfn.QUARTILE.INC('1. Data Original'!E15:E18,2) -> 7.36 | G16: =_xlfn.QUARTILE.INC('1. Data Original'!E15:E18,3) -> 8.4825 | H16: =MAX('1. Data Original'!E15:E18) -> 9.63 | I16: =((1/4)*SUM('1. Data Original'!J15:J18))/(C16^3) -> 0.29510441 | J16: =((1/4)*SUM('1. Data Original'!M15:M18))/(C16^4)-3 -> -1.4124087 | K16: =C16/B16*100 -> 19.040218
A18: Dengan BOBOT
A19: Data Tahun 2020
A20: Indikator | B20: Rata-rata | C20: Simpangan Baku | D20: Min | E20: Q1 | F20: Q2 | G20: Q3 | H20: Max | I20: Skewness | J20: Kurtosis | K20: CV (%)
A21: PPM | B21: =SUM('1. Data Original'!C29:C32) -> 9.2289567 | C21: =SQRT(SUM('1. Data Original'!H29:H32)) -> 3.1906127 | D21: =D4 -> 3.69 | E21: =E4 -> 4.305 | F21: =F4 -> 7.5 | G21: =G4 -> 11.11 | H21: =H4 -> 12.97 | I21: =(SUM('1. Data Original'!K29:K32))/(C21^3) -> -0.59686045 | J21: =(SUM('1. Data Original'!N29:N32))/(C21^4)-3 -> -1.1973217 | K21: =C21/B21*100 -> 34.571759
A22: RLS | B22: =SUM('1. Data Original'!D29:D32) -> 9.3588456 | C22: =SQRT(SUM('1. Data Original'!I29:I32)) -> 1.3751736 | D22: =D5 -> 8.19 | E22: =E5 -> 9.045 | F22: =F5 -> 9.6 | G22: =G5 -> 10.2475 | H22: =H5 -> 11.38 | I22: =(SUM('1. Data Original'!L29:L32))/(C22^3) -> 0.62494597 | J22: =(SUM('1. Data Original'!O29:O32))/(C22^4)-3 -> -1.363574 | K22: =C22/B22*100 -> 14.693838
A23: TPT | B23: =SUM('1. Data Original'!E29:E32) -> 11.014754 | C23: =SQRT(SUM('1. Data Original'!J29:J32)) -> 1.6167602 | D23: =D6 -> 7.99 | E23: =E6 -> 10.225 | F23: =F6 -> 11.61 | G23: =G6 -> 12.36 | H23: =H6 -> 12.69 | I23: =(SUM('1. Data Original'!M29:M32))/(C23^3) -> -1.0948588 | J23: =(SUM('1. Data Original'!P29:P32))/(C23^4)-3 -> -0.35898758 | K23: =C23/B23*100 -> 14.678133
A24: Data Tahun 2021
A25: Indikator | B25: Rata-rata | C25: Simpangan Baku | D25: Min | E25: Q1 | F25: Q2 | G25: Q3 | H25: Max | I25: Skewness | J25: Kurtosis | K25: CV (%)
A26: PPM | B26: =SUM('1. Data Original'!C35:C38) -> 9.7960807 | C26: =SQRT(SUM('1. Data Original'!H35:H38)) -> 3.2131626 | D26: =D9 -> 4.24 | E26: =E9 -> 4.765 | F26: =F9 -> 8.12 | G26: =G9 -> 11.7575 | H26: =H9 -> 13.13 | I26: =(SUM('1. Data Original'!K35:K38))/(C26^3) -> -0.73979111 | J26: =(SUM('1. Data Original'!N35:N38))/(C26^4)-3 -> -1.2056852 | K26: =C26/B26*100 -> 32.800491
A27: RLS | B27: =SUM('1. Data Original'!D35:D38) -> 9.4051477 | C27: =SQRT(SUM('1. Data Original'!I35:I38)) -> 1.3763181 | D27: =D10 -> 8.2 | E27: =E10 -> 9.19 | F27: =F10 -> 9.8 | G27: =G10 -> 10.4075 | H27: =H10 -> 11.39 | I27: =(SUM('1. Data Original'!L35:L38))/(C27^3) -> 0.54452054 | J27: =(SUM('1. Data Original'!O35:O38))/(C27^4)-3 -> -1.4305992 | K27: =C27/B27*100 -> 14.633669
A28: TPT | B28: =SUM('1. Data Original'!E35:E38) -> 9.6978112 | C28: =SQRT(SUM('1. Data Original'!J35:J38)) -> 1.9683562 | D28: =D11 -> 7.66 | E28: =E11 -> 7.7275 | F28: =F11 -> 8.94 | G28: =G11 -> 10.51 | H28: =H11 -> 11.65 | I28: =(SUM('1. Data Original'!M35:M38))/(C28^3) -> -0.017140105 | J28: =(SUM('1. Data Original'!P35:P38))/(C28^4)-3 -> -1.9985877 | K28: =C28/B28*100 -> 20.296912
A29: Data Tahun 2022
A30: Indikator | B30: Rata-rata | C30: Simpangan Baku | D30: Min | E30: Q1 | F30: Q2 | G30: Q3 | H30: Max | I30: Skewness | J30: Kurtosis | K30: CV (%)
A31: PPM | B31: =SUM('1. Data Original'!C41:C44) -> 9.4596749 | C31: =SQRT(SUM('1. Data Original'!H41:H44)) -> 3.0328639 | D31: =D14 -> 3.64 | E31: =E14 -> 4.585 | F31: =F14 -> 7.86 | G31: =G14 -> 11.295 | H31: =H14 -> 12.72 | I31: =(SUM('1. Data Original'!K41:K44))/(C31^3) -> -0.70515688 | J31: =(SUM('1. Data Original'!N41:N44))/(C31^4)-3 -> -1.2051479 | K31: =C31/B31*100 -> 32.060974
A32: RLS | B32: =SUM('1. Data Original'!D41:D44) -> 9.4584801 | C32: =SQRT(SUM('1. Data Original'!I41:I44)) -> 1.4273004 | D32: =D15 -> 8.22 | E32: =E15 -> 9.2025 | F32: =F15 -> 9.935 | G32: =G15 -> 10.6375 | H32: =H15 -> 11.53 | I32: =(SUM('1. Data Original'!L41:L44))/(C32^3) -> 0.57056528 | J32: =(SUM('1. Data Original'!O41:O44))/(C32^4)-3 -> -1.4083472 | K32: =C32/B32*100 -> 15.090167
A33: TPT | B33: =SUM('1. Data Original'!E41:E44) -> 7.9194694 | C33: =SQRT(SUM('1. Data Original'!J41:J44)) -> 1.7433426 | D33: =D16 -> 5.88 | E33: =E16 -> 6.435 | F33: =F16 -> 7.36 | G33: =G16 -> 8.4825 | H33: =H16 -> 9.63 | I33: =(SUM('1. Data Original'!M41:M44))/(C33^3) -> -0.0785983 | J33: =(SUM('1. Data Original'!P41:P44))/(C33^4)-3 -> -1.9193946 | K33: =C33/B33*100 -> 22.013377

Sheet 3. Standardisasi Z-Score
A1: Z-Score: z = (x - mean) / stdev
A2: Data Tahun 2020
A3: Kabupaten/Kota | B3: PPM | C3: RLS | D3: TPT
A4: ='1. Data Original'!B3 -> Kota Jakarta Pusat | B4: =('1. Data Original'!C3 - '2. Statistika Deskriptif'!B4) / '2. Statistika Deskriptif'!C4 -> -0.8674751 | C4: =('1. Data Original'!D3 - '2. Statistika Deskriptif'!B5) / '2. Statistika Deskriptif'!C5 -> 1.4704417 | D4: =('1. Data Original'!E3 - '2. Statistika Deskriptif'!B6) / '2. Statistika Deskriptif'!C6 -> -0.0027239666
A5: ='1. Data Original'!B4 -> Bandung Barat | B5: =('1. Data Original'!C4 - '2. Statistika Deskriptif'!B4) / '2. Statistika Deskriptif'!C4 -> 0.65602008 | C5: =('1. Data Original'!D4 - '2. Statistika Deskriptif'!B5) / '2. Statistika Deskriptif'!C5 -> -1.3092377 | D5: =('1. Data Original'!E4 - '2. Statistika Deskriptif'!B6) / '2. Statistika Deskriptif'!C6 -> 0.69461148
A6: ='1. Data Original'!B5 -> Kota Tasikmalaya | B6: =('1. Data Original'!C5 - '2. Statistika Deskriptif'!B4) / '2. Statistika Deskriptif'!C4 -> 1.2878375 | C6: =('1. Data Original'!D5 - '2. Statistika Deskriptif'!B5) / '2. Statistika Deskriptif'!C5 -> -0.31587266 | D6: =('1. Data Original'!E5 - '2. Statistika Deskriptif'!B6) / '2. Statistika Deskriptif'!C6 -> -1.626208
A7: ='1. Data Original'!B6 -> Kota Cilegon | B7: =('1. Data Original'!C6 - '2. Statistika Deskriptif'!B4) / '2. Statistika Deskriptif'!C4 -> -1.0763825 | C7: =('1. Data Original'!D6 - '2. Statistika Deskriptif'!B5) / '2. Statistika Deskriptif'!C5 -> 0.15466868 | D7: =('1. Data Original'!E6 - '2. Statistika Deskriptif'!B6) / '2. Statistika Deskriptif'!C6 -> 0.93432054
A8: Data Tahun 2021
A9: Kabupaten/Kota | B9: PPM | C9: RLS | D9: TPT
A10: ='1. Data Original'!B9 -> Kota Jakarta Pusat | B10: =('1. Data Original'!C9 - '2. Statistika Deskriptif'!B9) / '2. Statistika Deskriptif'!C9 -> -0.89356643 | C10: =('1. Data Original'!D9 - '2. Statistika Deskriptif'!B10) / '2. Statistika Deskriptif'!C10 -> 1.3907269 | D10: =('1. Data Original'!E9 - '2. Statistika Deskriptif'!B11) / '2. Statistika Deskriptif'!C11 -> -0.92056544
A11: ='1. Data Original'!B10 -> Bandung Barat | B11: =('1. Data Original'!C10 - '2. Statistika Deskriptif'!B9) / '2. Statistika Deskriptif'!C9 -> 0.74775703 | C11: =('1. Data Original'!D10 - '2. Statistika Deskriptif'!B10) / '2. Statistika Deskriptif'!C10 -> -1.3950934 | D11: =('1. Data Original'!E10 - '2. Statistika Deskriptif'!B11) / '2. Statistika Deskriptif'!C11 -> 1.3994379
A12: ='1. Data Original'!B11 -> Kota Tasikmalaya | B12: =('1. Data Original'!C11 - '2. Statistika Deskriptif'!B9) / '2. Statistika Deskriptif'!C9 -> 1.2200246 | C12: =('1. Data Original'!D11 - '2. Statistika Deskriptif'!B10) / '2. Statistika Deskriptif'!C10 -> -0.24234017 | D12: =('1. Data Original'!E11 - '2. Statistika Deskriptif'!B11) / '2. Statistika Deskriptif'!C11 -> -0.97410397
A13: ='1. Data Original'!B12 -> Kota Cilegon | B13: =('1. Data Original'!C12 - '2. Statistika Deskriptif'!B9) / '2. Statistika Deskriptif'!C9 -> -1.0742152 | C13: =('1. Data Original'!D12 - '2. Statistika Deskriptif'!B10) / '2. Statistika Deskriptif'!C10 -> 0.24670666 | D13: =('1. Data Original'!E12 - '2. Statistika Deskriptif'!B11) / '2. Statistika Deskriptif'!C11 -> 0.49523149
A14: Data Tahun 2022
A15: Kabupaten/Kota | B15: PPM | C15: RLS | D15: TPT
A16: ='1. Data Original'!B15 -> Kota Jakarta Pusat | B16: =('1. Data Original'!C15 - '2. Statistika Deskriptif'!B14) / '2. Statistika Deskriptif'!C14 -> -0.81342176 | C16: =('1. Data Original'!D15 - '2. Statistika Deskriptif'!B15) / '2. Statistika Deskriptif'!C15 -> 1.348362 | D16: =('1. Data Original'!E15 - '2. Statistika Deskriptif'!B16) / '2. Statistika Deskriptif'!C16 -> -1.1657689
A17: ='1. Data Original'!B16 -> Bandung Barat | B17: =('1. Data Original'!C16 - '2. Statistika Deskriptif'!B14) / '2. Statistika Deskriptif'!C14 -> 0.72999388 | C17: =('1. Data Original'!D16 - '2. Statistika Deskriptif'!B15) / '2. Statistika Deskriptif'!C15 -> -1.3981477 | D17: =('1. Data Original'!E16 - '2. Statistika Deskriptif'!B16) / '2. Statistika Deskriptif'!C16 -> 1.4402718
A18: ='1. Data Original'!B17 -> Kota Tasikmalaya | B18: =('1. Data Original'!C17 - '2. Statistika Deskriptif'!B14) / '2. Statistika Deskriptif'!C14 -> 1.2253469 | C18: =('1. Data Original'!D17 - '2. Statistika Deskriptif'!B15) / '2. Statistika Deskriptif'!C15 -> -0.31116046 | D18: =('1. Data Original'!E17 - '2. Statistika Deskriptif'!B16) / '2. Statistika Deskriptif'!C16 -> -0.65151018
A19: ='1. Data Original'!B18 -> Kota Cilegon | B19: =('1. Data Original'!C18 - '2. Statistika Deskriptif'!B14) / '2. Statistika Deskriptif'!C14 -> -1.141919 | C19: =('1. Data Original'!D18 - '2. Statistika Deskriptif'!B15) / '2. Statistika Deskriptif'!C15 -> 0.36094614 | D19: =('1. Data Original'!E18 - '2. Statistika Deskriptif'!B16) / '2. Statistika Deskriptif'!C16 -> 0.37700722
A20: Z-Score transpose
A21: Data Tahun 2020
A22: Variabel | B22: Kota Jakarta Pusat | C22: Bandung Barat | D22: Kota Tasikmalaya | E22: Kota Cilegon
A23: PPM | B23: -0.8674751 | C23: 0.65602008 | D23: 1.2878375 | E23: -1.0763825
A24: RLS | B24: 1.4704417 | C24: -1.3092377 | D24: -0.31587266 | E24: 0.15466868
A25: TPT | B25: -0.0027239666 | C25: 0.69461148 | D25: -1.626208 | E25: 0.93432054
A26: Data Tahun 2021
A27: Kabupaten/Kota | B27: Kota Jakarta Pusat | C27: Bandung Barat | D27: Kota Tasikmalaya | E27: Kota Cilegon
A28: PPM | B28: -0.89356643 | C28: 0.74775703 | D28: 1.2200246 | E28: -1.0742152
A29: RLS | B29: 1.3907269 | C29: -1.3950934 | D29: -0.24234017 | E29: 0.24670666
A30: TPT | B30: -0.92056544 | C30: 1.3994379 | D30: -0.97410397 | E30: 0.49523149
A31: Data Tahun 2022
A32: Kabupaten/Kota | B32: Kota Jakarta Pusat | C32: Bandung Barat | D32: Kota Tasikmalaya | E32: Kota Cilegon
A33: PPM | B33: -0.81342176 | C33: 0.72999388 | D33: 1.2253469 | E33: -1.141919
A34: RLS | B34: 1.348362 | C34: -1.3981477 | D34: -0.31116046 | E34: 0.36094614
A35: TPT | B35: -1.1657689 | C35: 1.4402718 | D35: -0.65151018 | E35: 0.37700722
A38: Z-Score: z = (x - mean) / stdev
A39: =A2 -> Data Tahun 2020
A40: =A3 -> Kabupaten/Kota | B40: PPM | C40: RLS | D40: TPT
A41: =A4 -> Kota Jakarta Pusat | B41: =('1. Data Original'!C3 - '2. Statistika Deskriptif'!B21) / '2. Statistika Deskriptif'!C21 -> -1.4790127 | C41: =('1. Data Original'!D3 - '2. Statistika Deskriptif'!B22) / '2. Statistika Deskriptif'!C22 -> 1.4697449 | D41: =('1. Data Original'!E3 - '2. Statistika Deskriptif'!B23) / '2. Statistika Deskriptif'!C23 -> -0.027681235 | G41: ='1. Data Original'!$E21*B41 -> -0.8023835 | H41: ='1. Data Original'!$E21*C41 -> 0.7973556 | I41: ='1. Data Original'!$E21*D41 -> -0.015017428 | K41: -0.8023835 | L41: 0.28059351 | M41: 0.52638282 | N41: -0.019212738
A42: =A5 -> Bandung Barat | B42: =('1. Data Original'!C4 - '2. Statistika Deskriptif'!B21) / '2. Statistika Deskriptif'!C21 -> 0.39523546 | C42: =('1. Data Original'!D4 - '2. Statistika Deskriptif'!B22) / '2. Statistika Deskriptif'!C22 -> -0.84996221 | D42: =('1. Data Original'!E4 - '2. Statistika Deskriptif'!B23) / '2. Statistika Deskriptif'!C23 -> 0.76402555 | G42: ='1. Data Original'!$E22*B42 -> 0.28059351 | H42: ='1. Data Original'!$E22*C42 -> -0.60342228 | I42: ='1. Data Original'!$E22*D42 -> 0.5424124 | K42: 0.7973556 | L42: -0.60342228 | M42: -0.009416838 | N42: 0.0041136748
...

Sheet 4. STATIS Intra-struktur
A1: Matriks W (Produk Skalar antar Wilayah) | B1: W1 = Z1 * Z1^T
A2: Data Tahun 2020
A3: Score | B3: ='3. Standardisasi Z-Score'!A4 -> Kota Jakarta Pusat | C3: ='3. Standardisasi Z-Score'!A5 -> Bandung Barat | D3: ='3. Standardisasi Z-Score'!A6 -> Kota Tasikmalaya | E3: ='3. Standardisasi Z-Score'!A7 -> Kota Cilegon
A4: ='3. Standardisasi Z-Score'!A4 -> Kota Jakarta Pusat | B4: =SUMPRODUCT('3. Standardisasi Z-Score'!$B4:$D4, '3. Standardisasi Z-Score'!$B4:$D4) -> 2.9147192 | C4: =SUMPRODUCT('3. Standardisasi Z-Score'!$B4:$D4, '3. Standardisasi Z-Score'!$B5:$D5) -> -2.4961309 | D4: =SUMPRODUCT('3. Standardisasi Z-Score'!$B4:$D4, '3. Standardisasi Z-Score'!$B6:$D6) -> -1.5772095 | E4: =SUMPRODUCT('3. Standardisasi Z-Score'!$B4:$D4, '3. Standardisasi Z-Score'!$B7:$D7) -> 1.1586212 | G4: =B4*B4 -> 8.4955879 | H4: =C4*C4 -> 6.2306693 | I4: =D4*D4 -> 2.4875899 | J4: =E4*E4 -> 1.3424031
A5: ='3. Standardisasi Z-Score'!A5 -> Bandung Barat | B5: =SUMPRODUCT('3. Standardisasi Z-Score'!$B5:$D5, '3. Standardisasi Z-Score'!$B4:$D4) -> -2.4961309 | C5: =SUMPRODUCT('3. Standardisasi Z-Score'!$B5:$D5, '3. Standardisasi Z-Score'!$B5:$D5) -> 2.6269508 | D5: =SUMPRODUCT('3. Standardisasi Z-Score'!$B5:$D5, '3. Standardisasi Z-Score'!$B6:$D6) -> 0.12881687 | E5: =SUMPRODUCT('3. Standardisasi Z-Score'!$B5:$D5, '3. Standardisasi Z-Score'!$B7:$D7) -> -0.25963681 | G5: =B5*B5 -> 6.2306693 | H5: =C5*C5 -> 6.9008705 | I5: =D5*D5 -> 0.016593786 | J5: =E5*E5 -> 0.067411275
A6: ='3. Standardisasi Z-Score'!A6 -> Kota Tasikmalaya | B6: =SUMPRODUCT('3. Standardisasi Z-Score'!$B6:$D6, '3. Standardisasi Z-Score'!$B4:$D4) -> -1.5772095 | C6: =SUMPRODUCT('3. Standardisasi Z-Score'!$B6:$D6, '3. Standardisasi Z-Score'!$B5:$D5) -> 0.12881687 | D6: =SUMPRODUCT('3. Standardisasi Z-Score'!$B6:$D6, '3. Standardisasi Z-Score'!$B6:$D6) -> 4.4028535 | E6: =SUMPRODUCT('3. Standardisasi Z-Score'!$B6:$D6, '3. Standardisasi Z-Score'!$B7:$D7) -> -2.9544609 | G6: =B6*B6 -> 2.4875899 | H6: =C6*C6 -> 0.016593786 | I6: =D6*D6 -> 19.385119 | J6: =E6*E6 -> 8.728839
A7: ='3. Standardisasi Z-Score'!A7 -> Kota Cilegon | B7: =SUMPRODUCT('3. Standardisasi Z-Score'!$B7:$D7, '3. Standardisasi Z-Score'!$B4:$D4) -> 1.1586212 | C7: =SUMPRODUCT('3. Standardisasi Z-Score'!$B7:$D7, '3. Standardisasi Z-Score'!$B5:$D5) -> -0.25963681 | D7: =SUMPRODUCT('3. Standardisasi Z-Score'!$B7:$D7, '3. Standardisasi Z-Score'!$B6:$D6) -> -2.9544609 | E7: =SUMPRODUCT('3. Standardisasi Z-Score'!$B7:$D7, '3. Standardisasi Z-Score'!$B7:$D7) -> 2.0554765 | G7: =B7*B7 -> 1.3424031 | H7: =C7*C7 -> 0.067411275 | I7: =D7*D7 -> 8.728839 | J7: =E7*E7 -> 4.2249836 | L7: =SUM(G4:J7) -> 76.753574
A8: Data Tahun 2021
A9: Score | B9: ='3. Standardisasi Z-Score'!A10 -> Kota Jakarta Pusat | C9: ='3. Standardisasi Z-Score'!A11 -> Bandung Barat | D9: ='3. Standardisasi Z-Score'!A12 -> Kota Tasikmalaya | E9: ='3. Standardisasi Z-Score'!A13 -> Kota Cilegon
A10: ='3. Standardisasi Z-Score'!A10 -> Kota Jakarta Pusat | B10: =SUMPRODUCT('3. Standardisasi Z-Score'!$B10:$D10, '3. Standardisasi Z-Score'!$B10:$D10) -> 3.5800231 | C10: =SUMPRODUCT('3. Standardisasi Z-Score'!$B10:$D10, '3. Standardisasi Z-Score'!$B11:$D11) -> -3.8966388 | D10: =SUMPRODUCT('3. Standardisasi Z-Score'!$B10:$D10, '3. Standardisasi Z-Score'!$B12:$D12) -> -0.5304756 | E10: =SUMPRODUCT('3. Standardisasi Z-Score'!$B10:$D10, '3. Standardisasi Z-Score'!$B13:$D13) -> 0.84709128 | G10: =B10*B10 -> 12.816565 | H10: =C10*C10 -> 15.183794 | I10: =D10*D10 -> 0.28140437 | J10: =E10*E10 -> 0.71756363
A11: ='3. Standardisasi Z-Score'!A11 -> Bandung Barat | B11: =SUMPRODUCT('3. Standardisasi Z-Score'!$B11:$D11, '3. Standardisasi Z-Score'!$B10:$D10) -> -3.8966388 | C11: =SUMPRODUCT('3. Standardisasi Z-Score'!$B11:$D11, '3. Standardisasi Z-Score'!$B11:$D11) -> 4.4638527 | D11: =SUMPRODUCT('3. Standardisasi Z-Score'!$B11:$D11, '3. Standardisasi Z-Score'!$B12:$D12) -> -0.11282887 | E11: =SUMPRODUCT('3. Standardisasi Z-Score'!$B11:$D11, '3. Standardisasi Z-Score'!$B13:$D13) -> -0.45438511 | G11: =B11*B11 -> 15.183794 | H11: =C11*C11 -> 19.925981 | I11: =D11*D11 -> 0.012730354 | J11: =E11*E11 -> 0.20646583
A12: ='3. Standardisasi Z-Score'!A12 -> Kota Tasikmalaya | B12: =SUMPRODUCT('3. Standardisasi Z-Score'!$B12:$D12, '3. Standardisasi Z-Score'!$B10:$D10) -> -0.5304756 | C12: =SUMPRODUCT('3. Standardisasi Z-Score'!$B12:$D12, '3. Standardisasi Z-Score'!$B11:$D11) -> -0.11282887 | D12: =SUMPRODUCT('3. Standardisasi Z-Score'!$B12:$D12, '3. Standardisasi Z-Score'!$B12:$D12) -> 2.4960674 | E12: =SUMPRODUCT('3. Standardisasi Z-Score'!$B12:$D12, '3. Standardisasi Z-Score'!$B13:$D13) -> -1.8527629 | G12: =B12*B12 -> 0.28140437 | H12: =C12*C12 -> 0.012730354 | I12: =D12*D12 -> 6.2303525 | J12: =E12*E12 -> 3.4327305
A13: ='3. Standardisasi Z-Score'!A13 -> Kota Cilegon | B13: =SUMPRODUCT('3. Standardisasi Z-Score'!$B13:$D13, '3. Standardisasi Z-Score'!$B10:$D10) -> 0.84709128 | C13: =SUMPRODUCT('3. Standardisasi Z-Score'!$B13:$D13, '3. Standardisasi Z-Score'!$B11:$D11) -> -0.45438511 | D13: =SUMPRODUCT('3. Standardisasi Z-Score'!$B13:$D13, '3. Standardisasi Z-Score'!$B12:$D12) -> -1.8527629 | E13: =SUMPRODUCT('3. Standardisasi Z-Score'!$B13:$D13, '3. Standardisasi Z-Score'!$B13:$D13) -> 1.4600568 | G13: =B13*B13 -> 0.71756363 | H13: =C13*C13 -> 0.20646583 | I13: =D13*D13 -> 3.4327305 | J13: =E13*E13 -> 2.1317658 | L13: =SUM(G10:J13) -> 80.774041
A14: Data Tahun 2022
A15: Score | B15: ='3. Standardisasi Z-Score'!A16 -> Kota Jakarta Pusat | C15: ='3. Standardisasi Z-Score'!A17 -> Bandung Barat | D15: ='3. Standardisasi Z-Score'!A18 -> Kota Tasikmalaya | E15: ='3. Standardisasi Z-Score'!A19 -> Kota Cilegon
A16: ='3. Standardisasi Z-Score'!A16 -> Kota Jakarta Pusat | B16: =SUMPRODUCT('3. Standardisasi Z-Score'!$B16:$D16, '3. Standardisasi Z-Score'!$B16:$D16) -> 3.8387521 | C16: =SUMPRODUCT('3. Standardisasi Z-Score'!$B16:$D16, '3. Standardisasi Z-Score'!$B17:$D17) -> -4.1580262 | D16: =SUMPRODUCT('3. Standardisasi Z-Score'!$B16:$D16, '3. Standardisasi Z-Score'!$B18:$D18) -> -0.65677046 | E16: =SUMPRODUCT('3. Standardisasi Z-Score'!$B16:$D16, '3. Standardisasi Z-Score'!$B19:$D19) -> 0.97604453 | G16: =B16*B16 -> 14.736018 | H16: =C16*C16 -> 17.289182 | I16: =D16*D16 -> 0.43134744 | J16: =E16*E16 -> 0.95266293
A17: ='3. Standardisasi Z-Score'!A17 -> Bandung Barat | B17: =SUMPRODUCT('3. Standardisasi Z-Score'!$B17:$D17, '3. Standardisasi Z-Score'!$B16:$D16) -> -4.1580262 | C17: =SUMPRODUCT('3. Standardisasi Z-Score'!$B17:$D17, '3. Standardisasi Z-Score'!$B17:$D17) -> 4.562091 | D17: =SUMPRODUCT('3. Standardisasi Z-Score'!$B17:$D17, '3. Standardisasi Z-Score'!$B18:$D18) -> 0.39119225 | E17: =SUMPRODUCT('3. Standardisasi Z-Score'!$B17:$D17, '3. Standardisasi Z-Score'!$B19:$D19) -> -0.79525701 | G17: =B17*B17 -> 17.289182 | H17: =C17*C17 -> 20.812674 | I17: =D17*D17 -> 0.15303137 | J17: =E17*E17 -> 0.63243371
A18: ='3. Standardisasi Z-Score'!A18 -> Kota Tasikmalaya | B18: =SUMPRODUCT('3. Standardisasi Z-Score'!$B18:$D18, '3. Standardisasi Z-Score'!$B16:$D16) -> -0.65677046 | C18: =SUMPRODUCT('3. Standardisasi Z-Score'!$B18:$D18, '3. Standardisasi Z-Score'!$B17:$D17) -> 0.39119225 | D18: =SUMPRODUCT('3. Standardisasi Z-Score'!$B18:$D18, '3. Standardisasi Z-Score'!$B18:$D18) -> 2.0227613 | E18: =SUMPRODUCT('3. Standardisasi Z-Score'!$B18:$D18, '3. Standardisasi Z-Score'!$B19:$D19) -> -1.7571831 | G18: =B18*B18 -> 0.43134744 | H18: =C18*C18 -> 0.15303137 | I18: =D18*D18 -> 4.0915633 | J18: =E18*E18 -> 3.0876924
A19: ='3. Standardisasi Z-Score'!A19 -> Kota Cilegon | B19: =SUMPRODUCT('3. Standardisasi Z-Score'!$B19:$D19, '3. Standardisasi Z-Score'!$B16:$D16) -> 0.97604453 | C19: =SUMPRODUCT('3. Standardisasi Z-Score'!$B19:$D19, '3. Standardisasi Z-Score'!$B17:$D17) -> -0.79525701 | D19: =SUMPRODUCT('3. Standardisasi Z-Score'!$B19:$D19, '3. Standardisasi Z-Score'!$B18:$D18) -> -1.7571831 | E19: =SUMPRODUCT('3. Standardisasi Z-Score'!$B19:$D19, '3. Standardisasi Z-Score'!$B19:$D19) -> 1.5763956 | G19: =B19*B19 -> 0.95266293 | H19: =C19*C19 -> 0.63243371 | I19: =D19*D19 -> 3.0876924 | J19: =E19*E19 -> 2.485023 | L19: =SUM(G16:J19) -> 87.217978
A20: Matriks S (Produk Skalar antar Variabel)
A21: Data Tahun 2020
A22: Loadings | B22: ='3. Standardisasi Z-Score'!A23 -> PPM | C22: ='3. Standardisasi Z-Score'!A24 -> RLS | D22: ='3. Standardisasi Z-Score'!A25 -> TPT
A23: ='3. Standardisasi Z-Score'!A23 -> PPM | B23: =SUMPRODUCT('3. Standardisasi Z-Score'!$B23:$E23, '3. Standardisasi Z-Score'!$B23:$E23) -> 4 | C23: =SUMPRODUCT('3. Standardisasi Z-Score'!$B23:$E23, '3. Standardisasi Z-Score'!$B24:$E24) -> -2.7077331 | D23: =SUMPRODUCT('3. Standardisasi Z-Score'!$B23:$E23, '3. Standardisasi Z-Score'!$B25:$E25) -> -2.6419359 | G23: =B23*B23 -> 16 | H23: =C23*C23 -> 7.3318183 | I23: =D23*D23 -> 6.9798251
A24: ='3. Standardisasi Z-Score'!A24 -> RLS | B24: =SUMPRODUCT('3. Standardisasi Z-Score'!$B24:$E24, '3. Standardisasi Z-Score'!$B23:$E23) -> -2.7077331 | C24: =SUMPRODUCT('3. Standardisasi Z-Score'!$B24:$E24, '3. Standardisasi Z-Score'!$B24:$E24) -> 4 | D24: =SUMPRODUCT('3. Standardisasi Z-Score'!$B24:$E24, '3. Standardisasi Z-Score'!$B25:$E25) -> -0.25523219 | G24: =B24*B24 -> 7.3318183 | H24: =C24*C24 -> 16 | I24: =D24*D24 -> 0.065143469
A25: ='3. Standardisasi Z-Score'!A25 -> TPT | B25: =SUMPRODUCT('3. Standardisasi Z-Score'!$B25:$E25, '3. Standardisasi Z-Score'!$B23:$E23) -> -2.6419359 | C25: =SUMPRODUCT('3. Standardisasi Z-Score'!$B25:$E25, '3. Standardisasi Z-Score'!$B24:$E24) -> -0.25523219 | D25: =SUMPRODUCT('3. Standardisasi Z-Score'!$B25:$E25, '3. Standardisasi Z-Score'!$B25:$E25) -> 4 | G25: =B25*B25 -> 6.9798251 | H25: =C25*C25 -> 0.065143469 | I25: =D25*D25 -> 16 | L25: =SUM(G23:I25) -> 76.753574
A26: Data Tahun 2021
A27: Loadings | B27: ='3. Standardisasi Z-Score'!A28 -> PPM | C27: ='3. Standardisasi Z-Score'!A29 -> RLS | D27: ='3. Standardisasi Z-Score'!A30 -> TPT
A28: ='3. Standardisasi Z-Score'!A28 -> PPM | B28: =SUMPRODUCT('3. Standardisasi Z-Score'!$B28:$E28, '3. Standardisasi Z-Score'!$B28:$E28) -> 4 | C28: =SUMPRODUCT('3. Standardisasi Z-Score'!$B28:$E28, '3. Standardisasi Z-Score'!$B29:$E29) -> -2.8465748 | D28: =SUMPRODUCT('3. Standardisasi Z-Score'!$B28:$E28, '3. Standardisasi Z-Score'!$B30:$E30) -> 0.14860987 | G28: =B28*B28 -> 16 | H28: =C28*C28 -> 8.1029883 | I28: =D28*D28 -> 0.022084892
A29: ='3. Standardisasi Z-Score'!A29 -> RLS | B29: =SUMPRODUCT('3. Standardisasi Z-Score'!$B29:$E29, '3. Standardisasi Z-Score'!$B28:$E28) -> -2.8465748 | C29: =SUMPRODUCT('3. Standardisasi Z-Score'!$B29:$E29, '3. Standardisasi Z-Score'!$B29:$E29) -> 4 | D29: =SUMPRODUCT('3. Standardisasi Z-Score'!$B29:$E29, '3. Standardisasi Z-Score'!$B30:$E30) -> -2.8743604 | G29: =B29*B29 -> 8.1029883 | H29: =C29*C29 -> 16 | I29: =D29*D29 -> 8.2619475
A30: ='3. Standardisasi Z-Score'!A30 -> TPT | B30: =SUMPRODUCT('3. Standardisasi Z-Score'!$B30:$E30, '3. Standardisasi Z-Score'!$B28:$E28) -> 0.14860987 | C30: =SUMPRODUCT('3. Standardisasi Z-Score'!$B30:$E30, '3. Standardisasi Z-Score'!$B29:$E29) -> -2.8743604 | D30: =SUMPRODUCT('3. Standardisasi Z-Score'!$B30:$E30, '3. Standardisasi Z-Score'!$B30:$E30) -> 4 | G30: =B30*B30 -> 0.022084892 | H30: =C30*C30 -> 8.2619475 | I30: =D30*D30 -> 16 | L30: =SUM(G28:I30) -> 80.774041
A31: Data Tahun 2022
A32: Loadings | B32: ='3. Standardisasi Z-Score'!A33 -> PPM | C32: ='3. Standardisasi Z-Score'!A34 -> RLS | D32: ='3. Standardisasi Z-Score'!A35 -> TPT
A33: ='3. Standardisasi Z-Score'!A33 -> PPM | B33: =SUMPRODUCT('3. Standardisasi Z-Score'!$B33:$E33, '3. Standardisasi Z-Score'!$B33:$E33) -> 4 | C33: =SUMPRODUCT('3. Standardisasi Z-Score'!$B33:$E33, '3. Standardisasi Z-Score'!$B34:$E34) -> -2.910877 | D33: =SUMPRODUCT('3. Standardisasi Z-Score'!$B33:$E33, '3. Standardisasi Z-Score'!$B35:$E35) -> 0.77081372 | G33: =B33*B33 -> 16 | H33: =C33*C33 -> 8.4732049 | I33: =D33*D33 -> 0.5941538
A34: ='3. Standardisasi Z-Score'!A34 -> RLS | B34: =SUMPRODUCT('3. Standardisasi Z-Score'!$B34:$E34, '3. Standardisasi Z-Score'!$B33:$E33) -> -2.910877 | C34: =SUMPRODUCT('3. Standardisasi Z-Score'!$B34:$E34, '3. Standardisasi Z-Score'!$B34:$E34) -> 4 | D34: =SUMPRODUCT('3. Standardisasi Z-Score'!$B34:$E34, '3. Standardisasi Z-Score'!$B35:$E35) -> -3.2467877 | G34: =B34*B34 -> 8.4732049 | H34: =C34*C34 -> 16 | I34: =D34*D34 -> 10.54163
A35: ='3. Standardisasi Z-Score'!A35 -> TPT | B35: =SUMPRODUCT('3. Standardisasi Z-Score'!$B35:$E35, '3. Standardisasi Z-Score'!$B33:$E33) -> 0.77081372 | C35: =SUMPRODUCT('3. Standardisasi Z-Score'!$B35:$E35, '3. Standardisasi Z-Score'!$B34:$E34) -> -3.2467877 | D35: =SUMPRODUCT('3. Standardisasi Z-Score'!$B35:$E35, '3. Standardisasi Z-Score'!$B35:$E35) -> 4 | G35: =B35*B35 -> 0.5941538 | H35: =C35*C35 -> 10.54163 | I35: =D35*D35 -> 16 | L35: =SUM(G33:I35) -> 87.217978
A37: =A1 -> Matriks W (Produk Skalar antar Wilayah) | B37: W1 =(D^(1/2) * Z1) * (D^(1/2) * Z1)^T
A38: =A2 -> Data Tahun 2020
A39: =A3 -> Score | B39: =B3 -> Kota Jakarta Pusat | C39: =C3 -> Bandung Barat | D39: =D3 -> Kota Tasikmalaya | E39: =E3 -> Kota Cilegon
A40: =A4 -> Kota Jakarta Pusat | B40: {=MMULT('3. Standardisasi Z-Score'!G41:I44,'3. Standardisasi Z-Score'!K41:N43)} -> 1.2798208 | C40: -0.71443138 | D40: -0.41725632 | E40: 0.018523834 | G40: =B40*B40 -> 1.6379412 | H40: =C40*C40 -> 0.51041219 | I40: =D40*D40 -> 0.17410284 | J40: =E40*E40 -> 0.00034313242
A41: =A5 -> Bandung Barat | B41: -0.71443138 | C41: 0.73706238 | D41: -0.30219016 | E41: -0.0016531437 | G41: =B41*B41 -> 0.51041219 | H41: =C41*C41 -> 0.54326095 | I41: =D41*D41 -> 0.091318893 | J41: =E41*E41 -> 2.7328842e-06
...

Sheet 5. STATIS Inter-struktur
A1: Matriks Inter-struktur W dan Koefisien RV
A2: Matriks RV Score:
A3: RV(W1, W1) | B3: =SUMPRODUCT('4. STATIS Intra-struktur'!$B$4:$E$7, '4. STATIS Intra-struktur'!$B$4:$E$7) -> 76.753574 | C3: =SQRT(SUMSQ('4. STATIS Intra-struktur'!$B$4:$E$7)) -> 8.7609117 | D3: =SQRT(SUMSQ('4. STATIS Intra-struktur'!$B$4:$E$7)) -> 8.7609117 | E3: =C3*D3 -> 76.753574 | F3: =B3/E3 -> 1 | H3: =F3 -> 1 | I3: =F4 -> 0.89405233 | J3: =F5 -> 0.87153299 | L3: 1 | M3: {=MMULT($H$3:$J$5, L3:L5)} -> 2.7655853 | N3: =M3/SUM($M$3:$M$5) -> 0.32469613 | O3: =N3/SUM($M$3:$M$5) -> 0.038121253 | P3: =O3/SUM($M$3:$M$5) -> 0.0044756614 | Q3: =P3/SUM($M$3:$M$5) -> 0.00052546921 | R3: =Q3/SUM($M$3:$M$5) -> 6.1693204e-05 | S3: =R3/SUM($M$3:$M$5) -> 7.2431484e-06 | T3: =S3/SUM($M$3:$M$5) -> 8.5038861e-07 | U3: =T3/SUM($M$3:$M$5) -> 9.984067e-08 | ... AE3: =AD3/SUM($M$3:$M$5) -> 4.9683024e-17
A4: RV(W1,W2) | B4: =SUMPRODUCT('4. STATIS Intra-struktur'!$B$4:$E$7, '4. STATIS Intra-struktur'!$B$10:$E$13) -> 70.396027 | C4: =SQRT(SUMSQ('4. STATIS Intra-struktur'!$B$4:$E$7)) -> 8.7609117 | D4: =SQRT(SUMSQ('4. STATIS Intra-struktur'!$B$10:$E$13)) -> 8.987438 | E4: =C4*D4 -> 78.738151 | F4: =B4/E4 -> 0.89405233 | H4: =F6 -> 0.89405233 | I4: =F7 -> 1 | J4: =F8 -> 0.99314315 | L4: 1 | M4: 2.8871955 | N4: =M4/SUM($M$3:$M$5) -> 0.33897389 | O4: =N4/SUM($M$3:$M$5) -> 0.039797546 | P4: =O4/SUM($M$3:$M$5) -> 0.0046724682 | Q4: =P4/SUM($M$3:$M$5) -> 0.00054857549 | R4: =Q4/SUM($M$3:$M$5) -> 6.4406019e-05 | S4: =R4/SUM($M$3:$M$5) -> 7.5616489e-06 | T4: =S4/SUM($M$3:$M$5) -> 8.8778247e-07 | U4: =T4/SUM($M$3:$M$5) -> 1.0423093e-07 | ... AE4: =AD4/SUM($M$3:$M$5) -> 5.186772e-17
A5: RV(W1,W3) | B5: =SUMPRODUCT('4. STATIS Intra-struktur'!$B$4:$E$7, '4. STATIS Intra-struktur'!$B$16:$E$19) -> 71.307653 | C5: =SQRT(SUMSQ('4. STATIS Intra-struktur'!$B$4:$E$7)) -> 8.7609117 | D5: =SQRT(SUMSQ('4. STATIS Intra-struktur'!$B$16:$E$19)) -> 9.3390566 | E5: =C5*D5 -> 81.81865 | F5: =B5/E5 -> 0.87153299 | H5: =F9 -> 0.87153299 | I5: =F10 -> 0.99314315 | J5: =F11 -> 1 | L5: 1 | M5: 2.8646761 | N5: =M5/SUM($M$3:$M$5) -> 0.33632998 | O5: =N5/SUM($M$3:$M$5) -> 0.039487136 | P5: =O5/SUM($M$3:$M$5) -> 0.0046360242 | Q5: =P5/SUM($M$3:$M$5) -> 0.00054429676 | R5: =Q5/SUM($M$3:$M$5) -> 6.390367e-05 | S5: =R5/SUM($M$3:$M$5) -> 7.5026701e-06 | T5: =S5/SUM($M$3:$M$5) -> 8.8085801e-07 | U5: =T5/SUM($M$3:$M$5) -> 1.0341796e-07 | ... AE5: =AD5/SUM($M$3:$M$5) -> 5.1463165e-17
A6: RV(W2, W1) | B6: =SUMPRODUCT('4. STATIS Intra-struktur'!$B$10:$E$13, '4. STATIS Intra-struktur'!$B$4:$E$7) -> 70.396027 | C6: =SQRT(SUMSQ('4. STATIS Intra-struktur'!$B$10:$E$13)) -> 8.987438 | D6: =SQRT(SUMSQ('4. STATIS Intra-struktur'!$B$4:$E$7)) -> 8.7609117 | E6: =C6*D6 -> 78.738151 | F6: =B6/E6 -> 0.89405233 | M6: 2.880049 | N6: =M6/SQRT(SUMSQ($M$6:$M$8)) -> 0.56987252 | O6: =N6/SQRT(SUMSQ($M$6:$M$8)) -> 0.11276013 | P6: =O6/SQRT(SUMSQ($M$6:$M$8)) -> 0.022311738 | Q6: =P6/SQRT(SUMSQ($M$6:$M$8)) -> 0.004414802 | R6: =Q6/SQRT(SUMSQ($M$6:$M$8)) -> 0.00087355263 | S6: =R6/SQRT(SUMSQ($M$6:$M$8)) -> 0.00017284902 | T6: =S6/SQRT(SUMSQ($M$6:$M$8)) -> 3.4201468e-05 | U6: =T6/SQRT(SUMSQ($M$6:$M$8)) -> 6.7674116e-06 | ... Z6: =Y6/SQRT(SUMSQ($M$6:$M$8)) -> 2.0526353e-09
A7: RV(W2,W2) | B7: =SUMPRODUCT('4. STATIS Intra-struktur'!$B$10:$E$13, '4. STATIS Intra-struktur'!$B$10:$E$13) -> 80.774041 | C7: =SQRT(SUMSQ('4. STATIS Intra-struktur'!$B$10:$E$13)) -> 8.987438 | D7: =SQRT(SUMSQ('4. STATIS Intra-struktur'!$B$10:$E$13)) -> 8.987438 | E7: =C7*D7 -> 80.774041 | F7: =B7/E7 -> 1 | M7: 2.9420539 | N7: =M7/SQRT(SUMSQ($M$6:$M$8)) -> 0.58214136 | O7: =N7/SQRT(SUMSQ($M$6:$M$8)) -> 0.11518775 | P7: =O7/SQRT(SUMSQ($M$6:$M$8)) -> 0.022792089 | Q7: =P7/SQRT(SUMSQ($M$6:$M$8)) -> 0.0045098488 | R7: =Q7/SQRT(SUMSQ($M$6:$M$8)) -> 0.00089235943 | S7: =R7/SQRT(SUMSQ($M$6:$M$8)) -> 0.0001765703 | T7: =S7/SQRT(SUMSQ($M$6:$M$8)) -> 3.4937795e-05 | U7: =T7/SQRT(SUMSQ($M$6:$M$8)) -> 6.9131079e-06 | ... Z7: =Y7/SQRT(SUMSQ($M$6:$M$8)) -> 2.0968267e-09
A8: RV(W2,W3) | B8: =SUMPRODUCT('4. STATIS Intra-struktur'!$B$10:$E$13, '4. STATIS Intra-struktur'!$B$16:$E$19) -> 83.358668 | C8: =SQRT(SUMSQ('4. STATIS Intra-struktur'!$B$10:$E$13)) -> 8.987438 | D8: =SQRT(SUMSQ('4. STATIS Intra-struktur'!$B$16:$E$19)) -> 9.3390566 | E8: =C8*D8 -> 83.934192 | F8: =B8/E8 -> 0.99314315 | M8: 2.9310433 | N8: =M8/SQRT(SUMSQ($M$6:$M$8)) -> 0.57996271 | O8: =N8/SQRT(SUMSQ($M$6:$M$8)) -> 0.11475666 | P8: =O8/SQRT(SUMSQ($M$6:$M$8)) -> 0.02270679 | Q8: =P8/SQRT(SUMSQ($M$6:$M$8)) -> 0.0044929707 | R8: =Q8/SQRT(SUMSQ($M$6:$M$8)) -> 0.00088901979 | S8: =R8/SQRT(SUMSQ($M$6:$M$8)) -> 0.00017590949 | T8: =S8/SQRT(SUMSQ($M$6:$M$8)) -> 3.4807041e-05 | U8: =T8/SQRT(SUMSQ($M$6:$M$8)) -> 6.8872358e-06 | ... Z8: =Y8/SQRT(SUMSQ($M$6:$M$8)) -> 2.0889794e-09
A9: RV(W3, W1) | B9: =SUMPRODUCT('4. STATIS Intra-struktur'!$B$16:$E$19, '4. STATIS Intra-struktur'!$B$4:$E$7) -> 71.307653 | C9: =SQRT(SUMSQ('4. STATIS Intra-struktur'!$B$16:$E$19)) -> 9.3390566 | D9: =SQRT(SUMSQ('4. STATIS Intra-struktur'!$B$4:$E$7)) -> 8.7609117 | E9: =C9*D9 -> 81.81865 | F9: =B9/E9 -> 0.87153299 | L9: z3 | M9: {=MMULT($H$3:$J$5, Z3:Z5)} -> 6.316599e-12 | N9: =M9/Z3 -> 2.8361262 | O9: =SQRT($N9) * Z3 -> 3.7507708e-12 | P9: =O9/SUM(O$9:O$11) -> 0.32446693 | Q9: z6 | R9: {=MMULT($H$3:$J$5, Z6:Z8)} -> 5.7479225e-09 | S9: =R9/Z6 -> 2.8002649 | T9: =SQRT($S9) * Z6 -> 3.4348782e-09 | U9: =T9/SUM(T$9:T$11) -> 0.32674488
A10: RV(W3,W2) | B10: =SUMPRODUCT('4. STATIS Intra-struktur'!$B$16:$E$19, '4. STATIS Intra-struktur'!$B$10:$E$13) -> 83.358668 | C10: =SQRT(SUMSQ('4. STATIS Intra-struktur'!$B$16:$E$19)) -> 9.3390566 | D10: =SQRT(SUMSQ('4. STATIS Intra-struktur'!$B$10:$E$13)) -> 8.987438 | E10: =C10*D10 -> 83.934192 | F10: =B10/E10 -> 0.99314315 | L10: z4 | M10: 6.6075288e-12 | N10: =M10/Z4 -> 2.8417913 | O10: =SQRT($N10) * Z4 -> 3.9196111e-12 | P10: =O10/SUM(O$9:O$11) -> 0.33907274 | Q10: z7 | R10: 6.0066456e-09 | S10: =R10/Z7 -> 2.8646362 | T10: =SQRT($S10) * Z7 -> 3.5489287e-09 | U10: =T10/SUM(T$9:T$11) -> 0.337594
A11: RV(W3,W3) | B11: =SUMPRODUCT('4. STATIS Intra-struktur'!$B$16:$E$19, '4. STATIS Intra-struktur'!$B$16:$E$19) -> 87.217978 | C11: =SQRT(SUMSQ('4. STATIS Intra-struktur'!$B$16:$E$19)) -> 9.3390566 | D11: =SQRT(SUMSQ('4. STATIS Intra-struktur'!$B$16:$E$19)) -> 9.3390566 | E11: =C11*D11 -> 87.217978 | F11: =B11/E11 -> 1 | L11: z5 | M11: 6.5572495e-12 | N11: =M11/Z5 -> 2.8423364 | O11: =SQRT($N11) * Z5 -> 3.8894122e-12 | P11: =O11/SUM(O$9:O$11) -> 0.33646033 | Q11: z8 | R11: 5.9603678e-09 | S11: =R11/Z8 -> 2.853244 | T11: =SQRT($S11) * Z8 -> 3.5286095e-09 | U11: =T11/SUM(T$9:T$11) -> 0.33566112
L12: p3 | M12: {=MMULT($H$3:$J$5, P3:P5)} -> 0.01269354 | N12: =M12/P3 -> 2.8361262 | O12: =SQRT($N12) * P3 -> 0.0075373728 | P12: =O12/SUM(O$12:O$14) -> 0.32446693 | Q12: p6 | R12: {=MMULT($H$3:$J$5, P6:P8)} -> 0.062478775 | S12: =R12/P6 -> 2.8002649 | T12: =SQRT($S12) * P6 -> 0.037336444 | U12: =T12/SUM(T$12:T$14) -> 0.32674488
A13: Matriks Inter-struktur S dan Koefisien RV | L13: p4 | M13: 0.013278179 | N13: =M13/P4 -> 2.8417913 | O13: =SQRT($N13) * P4 -> 0.0078766662 | P13: =O13/SUM(O$12:O$14) -> 0.33907274 | Q13: p7 | R13: 0.065291044 | S13: =R13/P7 -> 2.8646362 | T13: =SQRT($S13) * P7 -> 0.038576149 | U13: =T13/SUM(T$12:T$14) -> 0.337594
A14: Matriks RV Loadings: | L14: p5 | M14: 0.01317714 | N14: =M14/P5 -> 2.8423364 | O14: =SQRT($N14) * P5 -> 0.0078159799 | P14: =O14/SUM(O$12:O$14) -> 0.33646033 | Q14: p8 | R14: 0.064788013 | S14: =R14/P8 -> 2.853244 | T14: =SQRT($S14) * P8 -> 0.038355284 | U14: =T14/SUM(T$12:T$14) -> 0.33566112
A15: RV(S1, S1) | B15: =SUMPRODUCT('4. STATIS Intra-struktur'!$B$23:$D$25, '4. STATIS Intra-struktur'!$B$23:$D$25) -> 76.753574 | C15: =SQRT(SUMSQ('4. STATIS Intra-struktur'!$B$23:$D$25)) -> 8.7609117 | D15: =SQRT(SUMSQ('4. STATIS Intra-struktur'!$B$23:$D$25)) -> 8.7609117 | E15: =C15*D15 -> 76.753574 | F15: =B15/E15 -> 1 | H15: =F15 -> 1 | I15: =F16 -> 0.81405967 | J15: =F17 -> 0.74980758 | L15: m3 | M15: {=MMULT($H$3:$J$5, M3:M5)} -> 7.8435489 | N15: =M15/M3 -> 2.8361262 | O15: =SQRT($N15) * M3 -> 4.6574675 | P15: =O15/SUM(O$15:O$17) -> 0.32446693 | Q15: m3 | R15: {=MMULT($H$3:$J$5, M6:M8)} -> 8.0649 | S15: =R15/M6 -> 2.8002649 | T15: =SQRT($S15) * M6 -> 4.8194717 | U15: =T15/SUM(T$15:T$17) -> 0.32674488
A16: RV(S1,S2) | B16: =SUMPRODUCT('4. STATIS Intra-struktur'!$B$23:$D$25, '4. STATIS Intra-struktur'!$B$28:$D$30) -> 64.097553 | C16: =SQRT(SUMSQ('4. STATIS Intra-struktur'!$B$23:$D$25)) -> 8.7609117 | D16: =SQRT(SUMSQ('4. STATIS Intra-struktur'!$B$28:$D$30)) -> 8.987438 | E16: =C16*D16 -> 78.738151 | F16: =B16/E16 -> 0.81405967 | H16: =F18 -> 0.81405967 | I16: =F19 -> 1 | J16: =F20 -> 0.99442234 | L16: m4 | M16: 8.204807 | N16: =M16/M4 -> 2.8417913 | O16: =SQRT($N16) * M4 -> 4.8671225 | P16: =O16/SUM(O$15:O$17) -> 0.33907274 | Q16: m4 | R16: 8.4279139 | S16: =R16/M7 -> 2.8646362 | T16: =SQRT($S16) * M7 -> 4.9794956 | U16: =T16/SUM(T$15:T$17) -> 0.337594
A17: RV(S1,S3) | B17: =SUMPRODUCT('4. STATIS Intra-struktur'!$B$23:$D$25, '4. STATIS Intra-struktur'!$B$33:$D$35) -> 61.348244 | C17: =SQRT(SUMSQ('4. STATIS Intra-struktur'!$B$23:$D$25)) -> 8.7609117 | D17: =SQRT(SUMSQ('4. STATIS Intra-struktur'!$B$33:$D$35)) -> 9.3390566 | E17: =C17*D17 -> 81.81865 | F17: =B17/E17 -> 0.74980758 | H17: =F21 -> 0.74980758 | I17: =F22 -> 0.99442234 | J17: =F23 -> 1 | L17: m5 | M17: 8.1423734 | N17: =M17/M5 -> 2.8423364 | O17: =SQRT($N17) * M5 -> 4.8296235 | P17: =O17/SUM(O$15:O$17) -> 0.33646033 | Q17: m5 | R17: 8.3629816 | S17: =R17/M8 -> 2.853244 | T17: =SQRT($S17) * M8 -> 4.9509859 | U17: =T17/SUM(T$15:T$17) -> 0.33566112
A18: RV(S2, S1) | B18: =SUMPRODUCT('4. STATIS Intra-struktur'!$B$28:$D$30, '4. STATIS Intra-struktur'!$B$23:$D$25) -> 64.097553 | C18: =SQRT(SUMSQ('4. STATIS Intra-struktur'!$B$28:$D$30)) -> 8.987438 | D18: =SQRT(SUMSQ('4. STATIS Intra-struktur'!$B$23:$D$25)) -> 8.7609117 | E18: =C18*D18 -> 78.738151 | F18: =B18/E18 -> 0.81405967
A19: RV(S2,S2) | B19: =SUMPRODUCT('4. STATIS Intra-struktur'!$B$28:$D$30, '4. STATIS Intra-struktur'!$B$28:$D$30) -> 80.774041 | C19: =SQRT(SUMSQ('4. STATIS Intra-struktur'!$B$28:$D$30)) -> 8.987438 | D19: =SQRT(SUMSQ('4. STATIS Intra-struktur'!$B$28:$D$30)) -> 8.987438 | E19: =C19*D19 -> 80.774041 | F19: =B19/E19 -> 1
A20: RV(S2,S3) | B20: =SUMPRODUCT('4. STATIS Intra-struktur'!$B$28:$D$30, '4. STATIS Intra-struktur'!$B$33:$D$35) -> 83.466035 | C20: =SQRT(SUMSQ('4. STATIS Intra-struktur'!$B$28:$D$30)) -> 8.987438 | D20: =SQRT(SUMSQ('4. STATIS Intra-struktur'!$B$33:$D$35)) -> 9.3390566 | E20: =C20*D20 -> 83.934192 | F20: =B20/E20 -> 0.99442234
A21: RV(S3, S1) | B21: =SUMPRODUCT('4. STATIS Intra-struktur'!$B$33:$D$35, '4. STATIS Intra-struktur'!$B$23:$D$25) -> 61.348244 | C21: =SQRT(SUMSQ('4. STATIS Intra-struktur'!$B$33:$D$35)) -> 9.3390566 | D21: =SQRT(SUMSQ('4. STATIS Intra-struktur'!$B$23:$D$25)) -> 8.7609117 | E21: =C21*D21 -> 81.81865 | F21: =B21/E21 -> 0.74980758
A22: RV(S3,S2) | B22: =SUMPRODUCT('4. STATIS Intra-struktur'!$B$33:$D$35, '4. STATIS Intra-struktur'!$B$28:$D$30) -> 83.466035 | C22: =SQRT(SUMSQ('4. STATIS Intra-struktur'!$B$33:$D$35)) -> 9.3390566 | D22: =SQRT(SUMSQ('4. STATIS Intra-struktur'!$B$28:$D$30)) -> 8.987438 | E22: =C22*D22 -> 83.934192 | F22: =B22/E22 -> 0.99442234
A23: RV(S3,S3) | B23: =SUMPRODUCT('4. STATIS Intra-struktur'!$B$33:$D$35, '4. STATIS Intra-struktur'!$B$33:$D$35) -> 87.217978 | C23: =SQRT(SUMSQ('4. STATIS Intra-struktur'!$B$33:$D$35)) -> 9.3390566 | D23: =SQRT(SUMSQ('4. STATIS Intra-struktur'!$B$33:$D$35)) -> 9.3390566 | E23: =C23*D23 -> 87.217978 | F23: =B23/E23 -> 1
